Workbook

Sheet MATRIZ INGRESO MES-PAIS
A1: MES | B1: El Salvador | C1: Chile | D1: Ecuador | E1: México | F1: Colombia | G1: República Dominicana | H1: Perú | I1: Paraguay | J1: Honduras | K1: Bolivia | L1: Argentina | M1: Guatemala | N1: Venezuela | O1: Uruguay | P1: Nicaragua | Q1: TOTAL MES
A2: 45658 | B2: =IFERROR(SUMIFS(INGRESOS!$J:$J,INGRESOS!$T:$T,B$1,INGRESOS!$A:$A,">="&$A2,INGRESOS!$A:$A,"<="&EOMONTH($A2,0)),0) -> 5970 | C2: =IFERROR(SUMIFS(INGRESOS!$J:$J,INGRESOS!$T:$T,C$1,INGRESOS!$A:$A,">="&$A2,INGRESOS!$A:$A,"<="&EOMONTH($A2,0)),0) -> 4983.5963 | D2: =IFERROR(SUMIFS(INGRESOS!$J:$J,INGRESOS!$T:$T,D$1,INGRESOS!$A:$A,">="&$A2,INGRESOS!$A:$A,"<="&EOMONTH($A2,0)),0) -> 0 | E2: =IFERROR(SUMIFS(INGRESOS!$J:$J,INGRESOS!$T:$T,E$1,INGRESOS!$A:$A,">="&$A2,INGRESOS!$A:$A,"<="&EOMONTH($A2,0)),0) -> 0 | F2: =IFERROR(SUMIFS(INGRESOS!$J:$J,INGRESOS!$T:$T,F$1,INGRESOS!$A:$A,">="&$A2,INGRESOS!$A:$A,"<="&EOMONTH($A2,0)),0) -> 0 | G2: =IFERROR(SUMIFS(INGRESOS!$J:$J,INGRESOS!$T:$T,G$1,INGRESOS!$A:$A,">="&$A2,INGRESOS!$A:$A,"<="&EOMONTH($A2,0)),0) -> 0 | H2: =IFERROR(SUMIFS(INGRESOS!$J:$J,INGRESOS!$T:$T,H$1,INGRESOS!$A:$A,">="&$A2,INGRESOS!$A:$A,"<="&EOMONTH($A2,0)),0) -> 0 | I2: =IFERROR(SUMIFS(INGRESOS!$J:$J,INGRESOS!$T:$T,I$1,INGRESOS!$A:$A,">="&$A2,INGRESOS!$A:$A,"<="&EOMONTH($A2,0)),0) -> 0 | ... P2: =IFERROR(SUMIFS(INGRESOS!$J:$J,INGRESOS!$T:$T,P$1,INGRESOS!$A:$A,">="&$A2,INGRESOS!$A:$A,"<="&EOMONTH($A2,0)),0) -> 0 | Q2: =+SUM(Tabla8[[#This Row],[El Salvador]:[Nicaragua]]) -> 10953.596
A3: 45689 | B3: =IFERROR(SUMIFS(INGRESOS!$J:$J,INGRESOS!$T:$T,B$1,INGRESOS!$A:$A,">="&$A3,INGRESOS!$A:$A,"<="&EOMONTH($A3,0)),0) -> 0 | C3: =IFERROR(SUMIFS(INGRESOS!$J:$J,INGRESOS!$T:$T,C$1,INGRESOS!$A:$A,">="&$A3,INGRESOS!$A:$A,"<="&EOMONTH($A3,0)),0) -> 10194.846 | D3: =IFERROR(SUMIFS(INGRESOS!$J:$J,INGRESOS!$T:$T,D$1,INGRESOS!$A:$A,">="&$A3,INGRESOS!$A:$A,"<="&EOMONTH($A3,0)),0) -> 0 | E3: =IFERROR(SUMIFS(INGRESOS!$J:$J,INGRESOS!$T:$T,E$1,INGRESOS!$A:$A,">="&$A3,INGRESOS!$A:$A,"<="&EOMONTH($A3,0)),0) -> 0 | F3: =IFERROR(SUMIFS(INGRESOS!$J:$J,INGRESOS!$T:$T,F$1,INGRESOS!$A:$A,">="&$A3,INGRESOS!$A:$A,"<="&EOMONTH($A3,0)),0) -> 0 | G3: =IFERROR(SUMIFS(INGRESOS!$J:$J,INGRESOS!$T:$T,G$1,INGRESOS!$A:$A,">="&$A3,INGRESOS!$A:$A,"<="&EOMONTH($A3,0)),0) -> 0 | H3: =IFERROR(SUMIFS(INGRESOS!$J:$J,INGRESOS!$T:$T,H$1,INGRESOS!$A:$A,">="&$A3,INGRESOS!$A:$A,"<="&EOMONTH($A3,0)),0) -> 0 | I3: =IFERROR(SUMIFS(INGRESOS!$J:$J,INGRESOS!$T:$T,I$1,INGRESOS!$A:$A,">="&$A3,INGRESOS!$A:$A,"<="&EOMONTH($A3,0)),0) -> 0 | ... P3: =IFERROR(SUMIFS(INGRESOS!$J:$J,INGRESOS!$T:$T,P$1,INGRESOS!$A:$A,">="&$A3,INGRESOS!$A:$A,"<="&EOMONTH($A3,0)),0) -> 0 | Q3: =+SUM(Tabla8[[#This Row],[El Salvador]:[Nicaragua]]) -> 10194.846
A4: 45717 | B4: =IFERROR(SUMIFS(INGRESOS!$J:$J,INGRESOS!$T:$T,B$1,INGRESOS!$A:$A,">="&$A4,INGRESOS!$A:$A,"<="&EOMONTH($A4,0)),0) -> 773.5 | C4: =IFERROR(SUMIFS(INGRESOS!$J:$J,INGRESOS!$T:$T,C$1,INGRESOS!$A:$A,">="&$A4,INGRESOS!$A:$A,"<="&EOMONTH($A4,0)),0) -> 9141.7076 | D4: =IFERROR(SUMIFS(INGRESOS!$J:$J,INGRESOS!$T:$T,D$1,INGRESOS!$A:$A,">="&$A4,INGRESOS!$A:$A,"<="&EOMONTH($A4,0)),0) -> 5570.0413 | E4: =IFERROR(SUMIFS(INGRESOS!$J:$J,INGRESOS!$T:$T,E$1,INGRESOS!$A:$A,">="&$A4,INGRESOS!$A:$A,"<="&EOMONTH($A4,0)),0) -> 7651.42 | F4: =IFERROR(SUMIFS(INGRESOS!$J:$J,INGRESOS!$T:$T,F$1,INGRESOS!$A:$A,">="&$A4,INGRESOS!$A:$A,"<="&EOMONTH($A4,0)),0) -> 1451 | G4: =IFERROR(SUMIFS(INGRESOS!$J:$J,INGRESOS!$T:$T,G$1,INGRESOS!$A:$A,">="&$A4,INGRESOS!$A:$A,"<="&EOMONTH($A4,0)),0) -> 483.5 | H4: =IFERROR(SUMIFS(INGRESOS!$J:$J,INGRESOS!$T:$T,H$1,INGRESOS!$A:$A,">="&$A4,INGRESOS!$A:$A,"<="&EOMONTH($A4,0)),0) -> 0 | I4: =IFERROR(SUMIFS(INGRESOS!$J:$J,INGRESOS!$T:$T,I$1,INGRESOS!$A:$A,">="&$A4,INGRESOS!$A:$A,"<="&EOMONTH($A4,0)),0) -> 0 | ... P4: =IFERROR(SUMIFS(INGRESOS!$J:$J,INGRESOS!$T:$T,P$1,INGRESOS!$A:$A,">="&$A4,INGRESOS!$A:$A,"<="&EOMONTH($A4,0)),0) -> 0 | Q4: =+SUM(Tabla8[[#This Row],[El Salvador]:[Nicaragua]]) -> 25071.169
A5: 45748 | B5: =IFERROR(SUMIFS(INGRESOS!$J:$J,INGRESOS!$T:$T,B$1,INGRESOS!$A:$A,">="&$A5,INGRESOS!$A:$A,"<="&EOMONTH($A5,0)),0) -> 773.5 | C5: =IFERROR(SUMIFS(INGRESOS!$J:$J,INGRESOS!$T:$T,C$1,INGRESOS!$A:$A,">="&$A5,INGRESOS!$A:$A,"<="&EOMONTH($A5,0)),0) -> 31289.041 | D5: =IFERROR(SUMIFS(INGRESOS!$J:$J,INGRESOS!$T:$T,D$1,INGRESOS!$A:$A,">="&$A5,INGRESOS!$A:$A,"<="&EOMONTH($A5,0)),0) -> 241.62 | E5: =IFERROR(SUMIFS(INGRESOS!$J:$J,INGRESOS!$T:$T,E$1,INGRESOS!$A:$A,">="&$A5,INGRESOS!$A:$A,"<="&EOMONTH($A5,0)),0) -> 12871.23 | F5: =IFERROR(SUMIFS(INGRESOS!$J:$J,INGRESOS!$T:$T,F$1,INGRESOS!$A:$A,">="&$A5,INGRESOS!$A:$A,"<="&EOMONTH($A5,0)),0) -> 5200 | G5: =IFERROR(SUMIFS(INGRESOS!$J:$J,INGRESOS!$T:$T,G$1,INGRESOS!$A:$A,">="&$A5,INGRESOS!$A:$A,"<="&EOMONTH($A5,0)),0) -> 0 | H5: =IFERROR(SUMIFS(INGRESOS!$J:$J,INGRESOS!$T:$T,H$1,INGRESOS!$A:$A,">="&$A5,INGRESOS!$A:$A,"<="&EOMONTH($A5,0)),0) -> 2934.75 | I5: =IFERROR(SUMIFS(INGRESOS!$J:$J,INGRESOS!$T:$T,I$1,INGRESOS!$A:$A,">="&$A5,INGRESOS!$A:$A,"<="&EOMONTH($A5,0)),0) -> 3871.91 | ... P5: =IFERROR(SUMIFS(INGRESOS!$J:$J,INGRESOS!$T:$T,P$1,INGRESOS!$A:$A,">="&$A5,INGRESOS!$A:$A,"<="&EOMONTH($A5,0)),0) -> 0 | Q5: =+SUM(Tabla8[[#This Row],[El Salvador]:[Nicaragua]]) -> 59179.123
A6: 45778 | B6: =IFERROR(SUMIFS(INGRESOS!$J:$J,INGRESOS!$T:$T,B$1,INGRESOS!$A:$A,">="&$A6,INGRESOS!$A:$A,"<="&EOMONTH($A6,0)),0) -> 4000 | C6: =IFERROR(SUMIFS(INGRESOS!$J:$J,INGRESOS!$T:$T,C$1,INGRESOS!$A:$A,">="&$A6,INGRESOS!$A:$A,"<="&EOMONTH($A6,0)),0) -> 6253.16 | D6: =IFERROR(SUMIFS(INGRESOS!$J:$J,INGRESOS!$T:$T,D$1,INGRESOS!$A:$A,">="&$A6,INGRESOS!$A:$A,"<="&EOMONTH($A6,0)),0) -> 6288.2 | E6: =IFERROR(SUMIFS(INGRESOS!$J:$J,INGRESOS!$T:$T,E$1,INGRESOS!$A:$A,">="&$A6,INGRESOS!$A:$A,"<="&EOMONTH($A6,0)),0) -> 16864.5 | F6: =IFERROR(SUMIFS(INGRESOS!$J:$J,INGRESOS!$T:$T,F$1,INGRESOS!$A:$A,">="&$A6,INGRESOS!$A:$A,"<="&EOMONTH($A6,0)),0) -> 7515 | G6: =IFERROR(SUMIFS(INGRESOS!$J:$J,INGRESOS!$T:$T,G$1,INGRESOS!$A:$A,">="&$A6,INGRESOS!$A:$A,"<="&EOMONTH($A6,0)),0) -> 0 | H6: =IFERROR(SUMIFS(INGRESOS!$J:$J,INGRESOS!$T:$T,H$1,INGRESOS!$A:$A,">="&$A6,INGRESOS!$A:$A,"<="&EOMONTH($A6,0)),0) -> 9427.71 | I6: =IFERROR(SUMIFS(INGRESOS!$J:$J,INGRESOS!$T:$T,I$1,INGRESOS!$A:$A,">="&$A6,INGRESOS!$A:$A,"<="&EOMONTH($A6,0)),0) -> 0 | ... P6: =IFERROR(SUMIFS(INGRESOS!$J:$J,INGRESOS!$T:$T,P$1,INGRESOS!$A:$A,">="&$A6,INGRESOS!$A:$A,"<="&EOMONTH($A6,0)),0) -> 0 | Q6: =+SUM(Tabla8[[#This Row],[El Salvador]:[Nicaragua]]) -> 57208.64
A7: 45809 | B7: =IFERROR(SUMIFS(INGRESOS!$J:$J,INGRESOS!$T:$T,B$1,INGRESOS!$A:$A,">="&$A7,INGRESOS!$A:$A,"<="&EOMONTH($A7,0)),0) -> 5828.16 | C7: =IFERROR(SUMIFS(INGRESOS!$J:$J,INGRESOS!$T:$T,C$1,INGRESOS!$A:$A,">="&$A7,INGRESOS!$A:$A,"<="&EOMONTH($A7,0)),0) -> 33923.677 | D7: =IFERROR(SUMIFS(INGRESOS!$J:$J,INGRESOS!$T:$T,D$1,INGRESOS!$A:$A,">="&$A7,INGRESOS!$A:$A,"<="&EOMONTH($A7,0)),0) -> 7028.6 | E7: =IFERROR(SUMIFS(INGRESOS!$J:$J,INGRESOS!$T:$T,E$1,INGRESOS!$A:$A,">="&$A7,INGRESOS!$A:$A,"<="&EOMONTH($A7,0)),0) -> 13509.11 | F7: =IFERROR(SUMIFS(INGRESOS!$J:$J,INGRESOS!$T:$T,F$1,INGRESOS!$A:$A,">="&$A7,INGRESOS!$A:$A,"<="&EOMONTH($A7,0)),0) -> 1934.75 | G7: =IFERROR(SUMIFS(INGRESOS!$J:$J,INGRESOS!$T:$T,G$1,INGRESOS!$A:$A,">="&$A7,INGRESOS!$A:$A,"<="&EOMONTH($A7,0)),0) -> 3869.75 | H7: =IFERROR(SUMIFS(INGRESOS!$J:$J,INGRESOS!$T:$T,H$1,INGRESOS!$A:$A,">="&$A7,INGRESOS!$A:$A,"<="&EOMONTH($A7,0)),0) -> 9228.38 | I7: =IFERROR(SUMIFS(INGRESOS!$J:$J,INGRESOS!$T:$T,I$1,INGRESOS!$A:$A,">="&$A7,INGRESOS!$A:$A,"<="&EOMONTH($A7,0)),0) -> 0 | ... P7: =IFERROR(SUMIFS(INGRESOS!$J:$J,INGRESOS!$T:$T,P$1,INGRESOS!$A:$A,">="&$A7,INGRESOS!$A:$A,"<="&EOMONTH($A7,0)),0) -> 0 | Q7: =+SUM(Tabla8[[#This Row],[El Salvador]:[Nicaragua]]) -> 80492.024
A8: 45839 | B8: =IFERROR(SUMIFS(INGRESOS!$J:$J,INGRESOS!$T:$T,B$1,INGRESOS!$A:$A,">="&$A8,INGRESOS!$A:$A,"<="&EOMONTH($A8,0)),0) -> 2224 | C8: =IFERROR(SUMIFS(INGRESOS!$J:$J,INGRESOS!$T:$T,C$1,INGRESOS!$A:$A,">="&$A8,INGRESOS!$A:$A,"<="&EOMONTH($A8,0)),0) -> 33461.017 | D8: =IFERROR(SUMIFS(INGRESOS!$J:$J,INGRESOS!$T:$T,D$1,INGRESOS!$A:$A,">="&$A8,INGRESOS!$A:$A,"<="&EOMONTH($A8,0)),0) -> 18819.6 | E8: =IFERROR(SUMIFS(INGRESOS!$J:$J,INGRESOS!$T:$T,E$1,INGRESOS!$A:$A,">="&$A8,INGRESOS!$A:$A,"<="&EOMONTH($A8,0)),0) -> 27679.19 | F8: =IFERROR(SUMIFS(INGRESOS!$J:$J,INGRESOS!$T:$T,F$1,INGRESOS!$A:$A,">="&$A8,INGRESOS!$A:$A,"<="&EOMONTH($A8,0)),0) -> 15852.61 | G8: =IFERROR(SUMIFS(INGRESOS!$J:$J,INGRESOS!$T:$T,G$1,INGRESOS!$A:$A,">="&$A8,INGRESOS!$A:$A,"<="&EOMONTH($A8,0)),0) -> 1783.8 | H8: =IFERROR(SUMIFS(INGRESOS!$J:$J,INGRESOS!$T:$T,H$1,INGRESOS!$A:$A,">="&$A8,INGRESOS!$A:$A,"<="&EOMONTH($A8,0)),0) -> 13293.749 | I8: =IFERROR(SUMIFS(INGRESOS!$J:$J,INGRESOS!$T:$T,I$1,INGRESOS!$A:$A,">="&$A8,INGRESOS!$A:$A,"<="&EOMONTH($A8,0)),0) -> 0 | ... P8: =IFERROR(SUMIFS(INGRESOS!$J:$J,INGRESOS!$T:$T,P$1,INGRESOS!$A:$A,">="&$A8,INGRESOS!$A:$A,"<="&EOMONTH($A8,0)),0) -> 0 | Q8: =+SUM(Tabla8[[#This Row],[El Salvador]:[Nicaragua]]) -> 137497.24
A9: 45870 | B9: =IFERROR(SUMIFS(INGRESOS!$J:$J,INGRESOS!$T:$T,B$1,INGRESOS!$A:$A,">="&$A9,INGRESOS!$A:$A,"<="&EOMONTH($A9,0)),0) -> 2284.95 | C9: =IFERROR(SUMIFS(INGRESOS!$J:$J,INGRESOS!$T:$T,C$1,INGRESOS!$A:$A,">="&$A9,INGRESOS!$A:$A,"<="&EOMONTH($A9,0)),0) -> 20911.007 | D9: =IFERROR(SUMIFS(INGRESOS!$J:$J,INGRESOS!$T:$T,D$1,INGRESOS!$A:$A,">="&$A9,INGRESOS!$A:$A,"<="&EOMONTH($A9,0)),0) -> 18711.717 | E9: =IFERROR(SUMIFS(INGRESOS!$J:$J,INGRESOS!$T:$T,E$1,INGRESOS!$A:$A,">="&$A9,INGRESOS!$A:$A,"<="&EOMONTH($A9,0)),0) -> 25697.33 | F9: =IFERROR(SUMIFS(INGRESOS!$J:$J,INGRESOS!$T:$T,F$1,INGRESOS!$A:$A,">="&$A9,INGRESOS!$A:$A,"<="&EOMONTH($A9,0)),0) -> 24522.35 | G9: =IFERROR(SUMIFS(INGRESOS!$J:$J,INGRESOS!$T:$T,G$1,INGRESOS!$A:$A,">="&$A9,INGRESOS!$A:$A,"<="&EOMONTH($A9,0)),0) -> 1547.5 | H9: =IFERROR(SUMIFS(INGRESOS!$J:$J,INGRESOS!$T:$T,H$1,INGRESOS!$A:$A,">="&$A9,INGRESOS!$A:$A,"<="&EOMONTH($A9,0)),0) -> 13018.945 | I9: =IFERROR(SUMIFS(INGRESOS!$J:$J,INGRESOS!$T:$T,I$1,INGRESOS!$A:$A,">="&$A9,INGRESOS!$A:$A,"<="&EOMONTH($A9,0)),0) -> 241.62 | ... P9: =IFERROR(SUMIFS(INGRESOS!$J:$J,INGRESOS!$T:$T,P$1,INGRESOS!$A:$A,">="&$A9,INGRESOS!$A:$A,"<="&EOMONTH($A9,0)),0) -> 0 | Q9: =+SUM(Tabla8[[#This Row],[El Salvador]:[Nicaragua]]) -> 140640.2
A10: 45901 | B10: =IFERROR(SUMIFS(INGRESOS!$J:$J,INGRESOS!$T:$T,B$1,INGRESOS!$A:$A,">="&$A10,INGRESOS!$A:$A,"<="&EOMONTH($A10,0)),0) -> 8404.35 | C10: =IFERROR(SUMIFS(INGRESOS!$J:$J,INGRESOS!$T:$T,C$1,INGRESOS!$A:$A,">="&$A10,INGRESOS!$A:$A,"<="&EOMONTH($A10,0)),0) -> 47474.003 | D10: =IFERROR(SUMIFS(INGRESOS!$J:$J,INGRESOS!$T:$T,D$1,INGRESOS!$A:$A,">="&$A10,INGRESOS!$A:$A,"<="&EOMONTH($A10,0)),0) -> 10735.85 | E10: =IFERROR(SUMIFS(INGRESOS!$J:$J,INGRESOS!$T:$T,E$1,INGRESOS!$A:$A,">="&$A10,INGRESOS!$A:$A,"<="&EOMONTH($A10,0)),0) -> 22794.6 | F10: =IFERROR(SUMIFS(INGRESOS!$J:$J,INGRESOS!$T:$T,F$1,INGRESOS!$A:$A,">="&$A10,INGRESOS!$A:$A,"<="&EOMONTH($A10,0)),0) -> 6528.61 | G10: =IFERROR(SUMIFS(INGRESOS!$J:$J,INGRESOS!$T:$T,G$1,INGRESOS!$A:$A,">="&$A10,INGRESOS!$A:$A,"<="&EOMONTH($A10,0)),0) -> 1426.56 | H10: =IFERROR(SUMIFS(INGRESOS!$J:$J,INGRESOS!$T:$T,H$1,INGRESOS!$A:$A,">="&$A10,INGRESOS!$A:$A,"<="&EOMONTH($A10,0)),0) -> 10634.458 | I10: =IFERROR(SUMIFS(INGRESOS!$J:$J,INGRESOS!$T:$T,I$1,INGRESOS!$A:$A,">="&$A10,INGRESOS!$A:$A,"<="&EOMONTH($A10,0)),0) -> 0 | ... P10: =IFERROR(SUMIFS(INGRESOS!$J:$J,INGRESOS!$T:$T,P$1,INGRESOS!$A:$A,">="&$A10,INGRESOS!$A:$A,"<="&EOMONTH($A10,0)),0) -> 2900.74 | Q10: =+SUM(Tabla8[[#This Row],[El Salvador]:[Nicaragua]]) -> 123609.3
A11: 45931 | B11: =IFERROR(SUMIFS(INGRESOS!$J:$J,INGRESOS!$T:$T,B$1,INGRESOS!$A:$A,">="&$A11,INGRESOS!$A:$A,"<="&EOMONTH($A11,0)),0) -> 4013.37 | C11: =IFERROR(SUMIFS(INGRESOS!$J:$J,INGRESOS!$T:$T,C$1,INGRESOS!$A:$A,">="&$A11,INGRESOS!$A:$A,"<="&EOMONTH($A11,0)),0) -> 26303.996 | D11: =IFERROR(SUMIFS(INGRESOS!$J:$J,INGRESOS!$T:$T,D$1,INGRESOS!$A:$A,">="&$A11,INGRESOS!$A:$A,"<="&EOMONTH($A11,0)),0) -> 15883.216 | E11: =IFERROR(SUMIFS(INGRESOS!$J:$J,INGRESOS!$T:$T,E$1,INGRESOS!$A:$A,">="&$A11,INGRESOS!$A:$A,"<="&EOMONTH($A11,0)),0) -> 23294.36 | F11: =IFERROR(SUMIFS(INGRESOS!$J:$J,INGRESOS!$T:$T,F$1,INGRESOS!$A:$A,">="&$A11,INGRESOS!$A:$A,"<="&EOMONTH($A11,0)),0) -> 15330.87 | G11: =IFERROR(SUMIFS(INGRESOS!$J:$J,INGRESOS!$T:$T,G$1,INGRESOS!$A:$A,">="&$A11,INGRESOS!$A:$A,"<="&EOMONTH($A11,0)),0) -> 2393.57 | H11: =IFERROR(SUMIFS(INGRESOS!$J:$J,INGRESOS!$T:$T,H$1,INGRESOS!$A:$A,">="&$A11,INGRESOS!$A:$A,"<="&EOMONTH($A11,0)),0) -> 11247.575 | I11: =IFERROR(SUMIFS(INGRESOS!$J:$J,INGRESOS!$T:$T,I$1,INGRESOS!$A:$A,">="&$A11,INGRESOS!$A:$A,"<="&EOMONTH($A11,0)),0) -> 0 | ... P11: =IFERROR(SUMIFS(INGRESOS!$J:$J,INGRESOS!$T:$T,P$1,INGRESOS!$A:$A,">="&$A11,INGRESOS!$A:$A,"<="&EOMONTH($A11,0)),0) -> 3579.5 | Q11: =+SUM(Tabla8[[#This Row],[El Salvador]:[Nicaragua]]) -> 115336.26
A12: 45962 | B12: =IFERROR(SUMIFS(INGRESOS!$J:$J,INGRESOS!$T:$T,B$1,INGRESOS!$A:$A,">="&$A12,INGRESOS!$A:$A,"<="&EOMONTH($A12,0)),0) -> 3626.62 | C12: =IFERROR(SUMIFS(INGRESOS!$J:$J,INGRESOS!$T:$T,C$1,INGRESOS!$A:$A,">="&$A12,INGRESOS!$A:$A,"<="&EOMONTH($A12,0)),0) -> 34104.14 | D12: =IFERROR(SUMIFS(INGRESOS!$J:$J,INGRESOS!$T:$T,D$1,INGRESOS!$A:$A,">="&$A12,INGRESOS!$A:$A,"<="&EOMONTH($A12,0)),0) -> 35237.233 | E12: =IFERROR(SUMIFS(INGRESOS!$J:$J,INGRESOS!$T:$T,E$1,INGRESOS!$A:$A,">="&$A12,INGRESOS!$A:$A,"<="&EOMONTH($A12,0)),0) -> 17004.6 | F12: =IFERROR(SUMIFS(INGRESOS!$J:$J,INGRESOS!$T:$T,F$1,INGRESOS!$A:$A,">="&$A12,INGRESOS!$A:$A,"<="&EOMONTH($A12,0)),0) -> 11079.7 | G12: =IFERROR(SUMIFS(INGRESOS!$J:$J,INGRESOS!$T:$T,G$1,INGRESOS!$A:$A,">="&$A12,INGRESOS!$A:$A,"<="&EOMONTH($A12,0)),0) -> 2393.57 | H12: =IFERROR(SUMIFS(INGRESOS!$J:$J,INGRESOS!$T:$T,H$1,INGRESOS!$A:$A,">="&$A12,INGRESOS!$A:$A,"<="&EOMONTH($A12,0)),0) -> 8569.74 | I12: =IFERROR(SUMIFS(INGRESOS!$J:$J,INGRESOS!$T:$T,I$1,INGRESOS!$A:$A,">="&$A12,INGRESOS!$A:$A,"<="&EOMONTH($A12,0)),0) -> 0 | ... P12: =IFERROR(SUMIFS(INGRESOS!$J:$J,INGRESOS!$T:$T,P$1,INGRESOS!$A:$A,">="&$A12,INGRESOS!$A:$A,"<="&EOMONTH($A12,0)),0) -> 3578.76 | Q12: =+SUM(Tabla8[[#This Row],[El Salvador]:[Nicaragua]]) -> 130999.57
A13: 45992 | B13: =IFERROR(SUMIFS(INGRESOS!$J:$J,INGRESOS!$T:$T,B$1,INGRESOS!$A:$A,">="&$A13,INGRESOS!$A:$A,"<="&EOMONTH($A13,0)),0) -> 3529.87 | C13: =IFERROR(SUMIFS(INGRESOS!$J:$J,INGRESOS!$T:$T,C$1,INGRESOS!$A:$A,">="&$A13,INGRESOS!$A:$A,"<="&EOMONTH($A13,0)),0) -> 31175.86 | D13: =IFERROR(SUMIFS(INGRESOS!$J:$J,INGRESOS!$T:$T,D$1,INGRESOS!$A:$A,">="&$A13,INGRESOS!$A:$A,"<="&EOMONTH($A13,0)),0) -> 21465.79 | E13: =IFERROR(SUMIFS(INGRESOS!$J:$J,INGRESOS!$T:$T,E$1,INGRESOS!$A:$A,">="&$A13,INGRESOS!$A:$A,"<="&EOMONTH($A13,0)),0) -> 26188.47 | F13: =IFERROR(SUMIFS(INGRESOS!$J:$J,INGRESOS!$T:$T,F$1,INGRESOS!$A:$A,">="&$A13,INGRESOS!$A:$A,"<="&EOMONTH($A13,0)),0) -> 12817.37 | G13: =IFERROR(SUMIFS(INGRESOS!$J:$J,INGRESOS!$T:$T,G$1,INGRESOS!$A:$A,">="&$A13,INGRESOS!$A:$A,"<="&EOMONTH($A13,0)),0) -> 2393.57 | H13: =IFERROR(SUMIFS(INGRESOS!$J:$J,INGRESOS!$T:$T,H$1,INGRESOS!$A:$A,">="&$A13,INGRESOS!$A:$A,"<="&EOMONTH($A13,0)),0) -> 7743.7911 | I13: =IFERROR(SUMIFS(INGRESOS!$J:$J,INGRESOS!$T:$T,I$1,INGRESOS!$A:$A,">="&$A13,INGRESOS!$A:$A,"<="&EOMONTH($A13,0)),0) -> 0 | ... P13: =IFERROR(SUMIFS(INGRESOS!$J:$J,INGRESOS!$T:$T,P$1,INGRESOS!$A:$A,">="&$A13,INGRESOS!$A:$A,"<="&EOMONTH($A13,0)),0) -> 3578.76 | Q13: =+SUM(Tabla8[[#This Row],[El Salvador]:[Nicaragua]]) -> 118222.47
A14: 46023 | B14: =IFERROR(SUMIFS(INGRESOS!$J:$J,INGRESOS!$T:$T,B$1,INGRESOS!$A:$A,">="&$A14,INGRESOS!$A:$A,"<="&EOMONTH($A14,0)),0) -> 2949.62 | C14: =IFERROR(SUMIFS(INGRESOS!$J:$J,INGRESOS!$T:$T,C$1,INGRESOS!$A:$A,">="&$A14,INGRESOS!$A:$A,"<="&EOMONTH($A14,0)),0) -> 25315.133 | D14: =IFERROR(SUMIFS(INGRESOS!$J:$J,INGRESOS!$T:$T,D$1,INGRESOS!$A:$A,">="&$A14,INGRESOS!$A:$A,"<="&EOMONTH($A14,0)),0) -> 22004.309 | E14: =IFERROR(SUMIFS(INGRESOS!$J:$J,INGRESOS!$T:$T,E$1,INGRESOS!$A:$A,">="&$A14,INGRESOS!$A:$A,"<="&EOMONTH($A14,0)),0) -> 24673.73 | F14: =IFERROR(SUMIFS(INGRESOS!$J:$J,INGRESOS!$T:$T,F$1,INGRESOS!$A:$A,">="&$A14,INGRESOS!$A:$A,"<="&EOMONTH($A14,0)),0) -> 27620.28 | G14: =IFERROR(SUMIFS(INGRESOS!$J:$J,INGRESOS!$T:$T,G$1,INGRESOS!$A:$A,">="&$A14,INGRESOS!$A:$A,"<="&EOMONTH($A14,0)),0) -> 3118.94 | H14: =IFERROR(SUMIFS(INGRESOS!$J:$J,INGRESOS!$T:$T,H$1,INGRESOS!$A:$A,">="&$A14,INGRESOS!$A:$A,"<="&EOMONTH($A14,0)),0) -> 12047.527 | I14: =IFERROR(SUMIFS(INGRESOS!$J:$J,INGRESOS!$T:$T,I$1,INGRESOS!$A:$A,">="&$A14,INGRESOS!$A:$A,"<="&EOMONTH($A14,0)),0) -> 0 | ... P14: =IFERROR(SUMIFS(INGRESOS!$J:$J,INGRESOS!$T:$T,P$1,INGRESOS!$A:$A,">="&$A14,INGRESOS!$A:$A,"<="&EOMONTH($A14,0)),0) -> 0 | Q14: =+SUM(Tabla8[[#This Row],[El Salvador]:[Nicaragua]]) -> 136271.11
A15: CASH IN PROM PAIS | B15: =+AVERAGE(B9:B14) -> 4134.7967 | C15: =+AVERAGE(C9:C14) -> 30880.69 | D15: =+AVERAGE(D9:D14) -> 20673.019 | E15: =+AVERAGE(E9:E14) -> 23275.515 | F15: =+AVERAGE(F9:F14) -> 16316.53 | G15: =+AVERAGE(G9:G14) -> 2212.285 | H15: =+AVERAGE(H9:H14) -> 10543.673 | I15: =+AVERAGE(I9:I14) -> 40.27 | ... P15: =+AVERAGE(P9:P14) -> 2272.96
A17: INGRESO PROGRAMADO
A18: MES | B18: El Salvador | C18: Chile | D18: Ecuador | E18: México | F18: Colombia | G18: República Dominicana | H18: Perú | I18: Paraguay | J18: Honduras | K18: Bolivia | L18: Argentina | M18: Guatemala | N18: Venezuela | O18: Uruguay | P18: Nicaragua | Q18: TOTAL MES
A19: 46054 | B19: =IFERROR(SUMIFS('CALENDARIO INGRESOS'!$I:$I,'CALENDARIO INGRESOS'!$C:$C,Tabla814[[#Headers],[El Salvador]],'CALENDARIO INGRESOS'!$G:$G,">="&$A19,'CALENDARIO INGRESOS'!$G:$G,"<="&EOMONTH($A19,0)),0) -> 2650 | C19: =IFERROR(SUMIFS('CALENDARIO INGRESOS'!$I:$I,'CALENDARIO INGRESOS'!$C:$C,Tabla814[[#Headers],[Chile]],'CALENDARIO INGRESOS'!$G:$G,">="&$A19,'CALENDARIO INGRESOS'!$G:$G,"<="&EOMONTH($A19,0)),0) -> 34354.54 | D19: =IFERROR(SUMIFS('CALENDARIO INGRESOS'!$I:$I,'CALENDARIO INGRESOS'!$C:$C,Tabla814[[#Headers],[Ecuador]],'CALENDARIO INGRESOS'!$G:$G,">="&$A19,'CALENDARIO INGRESOS'!$G:$G,"<="&EOMONTH($A19,0)),0) -> 25524 | E19: =IFERROR(SUMIFS('CALENDARIO INGRESOS'!$I:$I,'CALENDARIO INGRESOS'!$C:$C,Tabla814[[#Headers],[México]],'CALENDARIO INGRESOS'!$G:$G,">="&$A19,'CALENDARIO INGRESOS'!$G:$G,"<="&EOMONTH($A19,0)),0) -> 25039.63 | F19: =IFERROR(SUMIFS('CALENDARIO INGRESOS'!$I:$I,'CALENDARIO INGRESOS'!$C:$C,Tabla814[[#Headers],[Colombia]],'CALENDARIO INGRESOS'!$G:$G,">="&$A19,'CALENDARIO INGRESOS'!$G:$G,"<="&EOMONTH($A19,0)),0) -> 8350 | G19: =IFERROR(SUMIFS('CALENDARIO INGRESOS'!$I:$I,'CALENDARIO INGRESOS'!$C:$C,Tabla814[[#Headers],[República Dominicana]],'CALENDARIO INGRESOS'!$G:$G,">="&$A19,'CALENDARIO INGRESOS'!$G:$G,"<="&EOMONTH($A19,0)),0) -> 3475 | H19: =IFERROR(SUMIFS('CALENDARIO INGRESOS'!$I:$I,'CALENDARIO INGRESOS'!$C:$C,Tabla814[[#Headers],[Perú]],'CALENDARIO INGRESOS'!$G:$G,">="&$A19,'CALENDARIO INGRESOS'!$G:$G,"<="&EOMONTH($A19,0)),0) -> 9600 | I19: =IFERROR(SUMIFS('CALENDARIO INGRESOS'!$I:$I,'CALENDARIO INGRESOS'!$C:$C,Tabla814[[#Headers],[Paraguay]],'CALENDARIO INGRESOS'!$G:$G,">="&$A19,'CALENDARIO INGRESOS'!$G:$G,"<="&EOMONTH($A19,0)),0) -> 0 | J19: =IFERROR(SUMIFS('CALENDARIO INGRESOS'!$I:$I,'CALENDARIO INGRESOS'!$C:$C,Tabla814[[#Headers],[Honduras]],'CALENDARIO INGRESOS'!$G:$G,">="&$A19,'CALENDARIO INGRESOS'!$G:$G,"<="&EOMONTH($A19,0)),0) -> 1560 | K19: =IFERROR(SUMIFS('CALENDARIO INGRESOS'!$I:$I,'CALENDARIO INGRESOS'!$C:$C,Tabla814[[#Headers],[Bolivia]],'CALENDARIO INGRESOS'!$G:$G,">="&$A19,'CALENDARIO INGRESOS'!$G:$G,"<="&EOMONTH($A19,0)),0) -> 500 | L19: =IFERROR(SUMIFS('CALENDARIO INGRESOS'!$I:$I,'CALENDARIO INGRESOS'!$C:$C,Tabla814[[#Headers],[Argentina]],'CALENDARIO INGRESOS'!$G:$G,">="&$A19,'CALENDARIO INGRESOS'!$G:$G,"<="&EOMONTH($A19,0)),0) -> 2200 | M19: =IFERROR(SUMIFS('CALENDARIO INGRESOS'!$I:$I,'CALENDARIO INGRESOS'!$C:$C,Tabla814[[#Headers],[Guatemala]],'CALENDARIO INGRESOS'!$G:$G,">="&$A19,'CALENDARIO INGRESOS'!$G:$G,"<="&EOMONTH($A19,0)),0) -> 3450 | N19: =IFERROR(SUMIFS('CALENDARIO INGRESOS'!$I:$I,'CALENDARIO INGRESOS'!$C:$C,Tabla814[[#Headers],[Venezuela]],'CALENDARIO INGRESOS'!$G:$G,">="&$A19,'CALENDARIO INGRESOS'!$G:$G,"<="&EOMONTH($A19,0)),0) -> 12500 | O19: =IFERROR(SUMIFS('CALENDARIO INGRESOS'!$I:$I,'CALENDARIO INGRESOS'!$C:$C,Tabla814[[#Headers],[Uruguay]],'CALENDARIO INGRESOS'!$G:$G,">="&$A19,'CALENDARIO INGRESOS'!$G:$G,"<="&EOMONTH($A19,0)),0) -> 0 | P19: =IFERROR(SUMIFS('CALENDARIO INGRESOS'!$I:$I,'CALENDARIO INGRESOS'!$C:$C,Tabla814[[#Headers],[Nicaragua]],'CALENDARIO INGRESOS'!$G:$G,">="&$A19,'CALENDARIO INGRESOS'!$G:$G,"<="&EOMONTH($A19,0)),0) -> 0 | Q19: =+SUM(Tabla814[[#This Row],[El Salvador]:[Nicaragua]]) -> 129203.17
A20: 46082 | B20: =IFERROR(SUMIFS('CALENDARIO INGRESOS'!$I:$I,'CALENDARIO INGRESOS'!$C:$C,Tabla814[[#Headers],[El Salvador]],'CALENDARIO INGRESOS'!$G:$G,">="&$A20,'CALENDARIO INGRESOS'!$G:$G,"<="&EOMONTH($A20,0)),0) -> 2522 | C20: =IFERROR(SUMIFS('CALENDARIO INGRESOS'!$I:$I,'CALENDARIO INGRESOS'!$C:$C,Tabla814[[#Headers],[Chile]],'CALENDARIO INGRESOS'!$G:$G,">="&$A20,'CALENDARIO INGRESOS'!$G:$G,"<="&EOMONTH($A20,0)),0) -> 15515 | D20: =IFERROR(SUMIFS('CALENDARIO INGRESOS'!$I:$I,'CALENDARIO INGRESOS'!$C:$C,Tabla814[[#Headers],[Ecuador]],'CALENDARIO INGRESOS'!$G:$G,">="&$A20,'CALENDARIO INGRESOS'!$G:$G,"<="&EOMONTH($A20,0)),0) -> 17245 | E20: =IFERROR(SUMIFS('CALENDARIO INGRESOS'!$I:$I,'CALENDARIO INGRESOS'!$C:$C,Tabla814[[#Headers],[México]],'CALENDARIO INGRESOS'!$G:$G,">="&$A20,'CALENDARIO INGRESOS'!$G:$G,"<="&EOMONTH($A20,0)),0) -> 26888.63 | F20: =IFERROR(SUMIFS('CALENDARIO INGRESOS'!$I:$I,'CALENDARIO INGRESOS'!$C:$C,Tabla814[[#Headers],[Colombia]],'CALENDARIO INGRESOS'!$G:$G,">="&$A20,'CALENDARIO INGRESOS'!$G:$G,"<="&EOMONTH($A20,0)),0) -> 8350 | G20: =IFERROR(SUMIFS('CALENDARIO INGRESOS'!$I:$I,'CALENDARIO INGRESOS'!$C:$C,Tabla814[[#Headers],[República Dominicana]],'CALENDARIO INGRESOS'!$G:$G,">="&$A20,'CALENDARIO INGRESOS'!$G:$G,"<="&EOMONTH($A20,0)),0) -> 3475 | H20: =IFERROR(SUMIFS('CALENDARIO INGRESOS'!$I:$I,'CALENDARIO INGRESOS'!$C:$C,Tabla814[[#Headers],[Perú]],'CALENDARIO INGRESOS'!$G:$G,">="&$A20,'CALENDARIO INGRESOS'!$G:$G,"<="&EOMONTH($A20,0)),0) -> 13487 | I20: =IFERROR(SUMIFS('CALENDARIO INGRESOS'!$I:$I,'CALENDARIO INGRESOS'!$C:$C,Tabla814[[#Headers],[Paraguay]],'CALENDARIO INGRESOS'!$G:$G,">="&$A20,'CALENDARIO INGRESOS'!$G:$G,"<="&EOMONTH($A20,0)),0) -> 0 | J20: =IFERROR(SUMIFS('CALENDARIO INGRESOS'!$I:$I,'CALENDARIO INGRESOS'!$C:$C,Tabla814[[#Headers],[Honduras]],'CALENDARIO INGRESOS'!$G:$G,">="&$A20,'CALENDARIO INGRESOS'!$G:$G,"<="&EOMONTH($A20,0)),0) -> 1560 | K20: =IFERROR(SUMIFS('CALENDARIO INGRESOS'!$I:$I,'CALENDARIO INGRESOS'!$C:$C,Tabla814[[#Headers],[Bolivia]],'CALENDARIO INGRESOS'!$G:$G,">="&$A20,'CALENDARIO INGRESOS'!$G:$G,"<="&EOMONTH($A20,0)),0) -> 500 | L20: =IFERROR(SUMIFS('CALENDARIO INGRESOS'!$I:$I,'CALENDARIO INGRESOS'!$C:$C,Tabla814[[#Headers],[Argentina]],'CALENDARIO INGRESOS'!$G:$G,">="&$A20,'CALENDARIO INGRESOS'!$G:$G,"<="&EOMONTH($A20,0)),0) -> 2200 | M20: =IFERROR(SUMIFS('CALENDARIO INGRESOS'!$I:$I,'CALENDARIO INGRESOS'!$C:$C,Tabla814[[#Headers],[Guatemala]],'CALENDARIO INGRESOS'!$G:$G,">="&$A20,'CALENDARIO INGRESOS'!$G:$G,"<="&EOMONTH($A20,0)),0) -> 700 | N20: =IFERROR(SUMIFS('CALENDARIO INGRESOS'!$I:$I,'CALENDARIO INGRESOS'!$C:$C,Tabla814[[#Headers],[Venezuela]],'CALENDARIO INGRESOS'!$G:$G,">="&$A20,'CALENDARIO INGRESOS'!$G:$G,"<="&EOMONTH($A20,0)),0) -> 2000 | O20: =IFERROR(SUMIFS('CALENDARIO INGRESOS'!$I:$I,'CALENDARIO INGRESOS'!$C:$C,Tabla814[[#Headers],[Uruguay]],'CALENDARIO INGRESOS'!$G:$G,">="&$A20,'CALENDARIO INGRESOS'!$G:$G,"<="&EOMONTH($A20,0)),0) -> 0 | P20: =IFERROR(SUMIFS('CALENDARIO INGRESOS'!$I:$I,'CALENDARIO INGRESOS'!$C:$C,Tabla814[[#Headers],[Nicaragua]],'CALENDARIO INGRESOS'!$G:$G,">="&$A20,'CALENDARIO INGRESOS'!$G:$G,"<="&EOMONTH($A20,0)),0) -> 0 | Q20: =+SUM(Tabla814[[#This Row],[El Salvador]:[Nicaragua]]) -> 94442.63
A21: 46113 | B21: =IFERROR(SUMIFS('CALENDARIO INGRESOS'!$I:$I,'CALENDARIO INGRESOS'!$C:$C,Tabla814[[#Headers],[El Salvador]],'CALENDARIO INGRESOS'!$G:$G,">="&$A21,'CALENDARIO INGRESOS'!$G:$G,"<="&EOMONTH($A21,0)),0) -> 7850 | C21: =IFERROR(SUMIFS('CALENDARIO INGRESOS'!$I:$I,'CALENDARIO INGRESOS'!$C:$C,Tabla814[[#Headers],[Chile]],'CALENDARIO INGRESOS'!$G:$G,">="&$A21,'CALENDARIO INGRESOS'!$G:$G,"<="&EOMONTH($A21,0)),0) -> 16245 | D21: =IFERROR(SUMIFS('CALENDARIO INGRESOS'!$I:$I,'CALENDARIO INGRESOS'!$C:$C,Tabla814[[#Headers],[Ecuador]],'CALENDARIO INGRESOS'!$G:$G,">="&$A21,'CALENDARIO INGRESOS'!$G:$G,"<="&EOMONTH($A21,0)),0) -> 30404 | E21: =IFERROR(SUMIFS('CALENDARIO INGRESOS'!$I:$I,'CALENDARIO INGRESOS'!$C:$C,Tabla814[[#Headers],[México]],'CALENDARIO INGRESOS'!$G:$G,">="&$A21,'CALENDARIO INGRESOS'!$G:$G,"<="&EOMONTH($A21,0)),0) -> 25420.63 | F21: =IFERROR(SUMIFS('CALENDARIO INGRESOS'!$I:$I,'CALENDARIO INGRESOS'!$C:$C,Tabla814[[#Headers],[Colombia]],'CALENDARIO INGRESOS'!$G:$G,">="&$A21,'CALENDARIO INGRESOS'!$G:$G,"<="&EOMONTH($A21,0)),0) -> 14934 | G21: =IFERROR(SUMIFS('CALENDARIO INGRESOS'!$I:$I,'CALENDARIO INGRESOS'!$C:$C,Tabla814[[#Headers],[República Dominicana]],'CALENDARIO INGRESOS'!$G:$G,">="&$A21,'CALENDARIO INGRESOS'!$G:$G,"<="&EOMONTH($A21,0)),0) -> 2475 | H21: =IFERROR(SUMIFS('CALENDARIO INGRESOS'!$I:$I,'CALENDARIO INGRESOS'!$C:$C,Tabla814[[#Headers],[Perú]],'CALENDARIO INGRESOS'!$G:$G,">="&$A21,'CALENDARIO INGRESOS'!$G:$G,"<="&EOMONTH($A21,0)),0) -> 12200 | I21: =IFERROR(SUMIFS('CALENDARIO INGRESOS'!$I:$I,'CALENDARIO INGRESOS'!$C:$C,Tabla814[[#Headers],[Paraguay]],'CALENDARIO INGRESOS'!$G:$G,">="&$A21,'CALENDARIO INGRESOS'!$G:$G,"<="&EOMONTH($A21,0)),0) -> 0 | J21: =IFERROR(SUMIFS('CALENDARIO INGRESOS'!$I:$I,'CALENDARIO INGRESOS'!$C:$C,Tabla814[[#Headers],[Honduras]],'CALENDARIO INGRESOS'!$G:$G,">="&$A21,'CALENDARIO INGRESOS'!$G:$G,"<="&EOMONTH($A21,0)),0) -> 1560 | K21: =IFERROR(SUMIFS('CALENDARIO INGRESOS'!$I:$I,'CALENDARIO INGRESOS'!$C:$C,Tabla814[[#Headers],[Bolivia]],'CALENDARIO INGRESOS'!$G:$G,">="&$A21,'CALENDARIO INGRESOS'!$G:$G,"<="&EOMONTH($A21,0)),0) -> 500 | L21: =IFERROR(SUMIFS('CALENDARIO INGRESOS'!$I:$I,'CALENDARIO INGRESOS'!$C:$C,Tabla814[[#Headers],[Argentina]],'CALENDARIO INGRESOS'!$G:$G,">="&$A21,'CALENDARIO INGRESOS'!$G:$G,"<="&EOMONTH($A21,0)),0) -> 2200 | M21: =IFERROR(SUMIFS('CALENDARIO INGRESOS'!$I:$I,'CALENDARIO INGRESOS'!$C:$C,Tabla814[[#Headers],[Guatemala]],'CALENDARIO INGRESOS'!$G:$G,">="&$A21,'CALENDARIO INGRESOS'!$G:$G,"<="&EOMONTH($A21,0)),0) -> 700 | N21: =IFERROR(SUMIFS('CALENDARIO INGRESOS'!$I:$I,'CALENDARIO INGRESOS'!$C:$C,Tabla814[[#Headers],[Venezuela]],'CALENDARIO INGRESOS'!$G:$G,">="&$A21,'CALENDARIO INGRESOS'!$G:$G,"<="&EOMONTH($A21,0)),0) -> 2000 | O21: =IFERROR(SUMIFS('CALENDARIO INGRESOS'!$I:$I,'CALENDARIO INGRESOS'!$C:$C,Tabla814[[#Headers],[Uruguay]],'CALENDARIO INGRESOS'!$G:$G,">="&$A21,'CALENDARIO INGRESOS'!$G:$G,"<="&EOMONTH($A21,0)),0) -> 0 | P21: =IFERROR(SUMIFS('CALENDARIO INGRESOS'!$I:$I,'CALENDARIO INGRESOS'!$C:$C,Tabla814[[#Headers],[Nicaragua]],'CALENDARIO INGRESOS'!$G:$G,">="&$A21,'CALENDARIO INGRESOS'!$G:$G,"<="&EOMONTH($A21,0)),0) -> 0 | Q21: =+SUM(Tabla814[[#This Row],[El Salvador]:[Nicaragua]]) -> 116488.63
A22: 46143 | B22: =IFERROR(SUMIFS('CALENDARIO INGRESOS'!$I:$I,'CALENDARIO INGRESOS'!$C:$C,Tabla814[[#Headers],[El Salvador]],'CALENDARIO INGRESOS'!$G:$G,">="&$A22,'CALENDARIO INGRESOS'!$G:$G,"<="&EOMONTH($A22,0)),0) -> 1850 | C22: =IFERROR(SUMIFS('CALENDARIO INGRESOS'!$I:$I,'CALENDARIO INGRESOS'!$C:$C,Tabla814[[#Headers],[Chile]],'CALENDARIO INGRESOS'!$G:$G,">="&$A22,'CALENDARIO INGRESOS'!$G:$G,"<="&EOMONTH($A22,0)),0) -> 14750 | D22: =IFERROR(SUMIFS('CALENDARIO INGRESOS'!$I:$I,'CALENDARIO INGRESOS'!$C:$C,Tabla814[[#Headers],[Ecuador]],'CALENDARIO INGRESOS'!$G:$G,">="&$A22,'CALENDARIO INGRESOS'!$G:$G,"<="&EOMONTH($A22,0)),0) -> 15225 | E22: =IFERROR(SUMIFS('CALENDARIO INGRESOS'!$I:$I,'CALENDARIO INGRESOS'!$C:$C,Tabla814[[#Headers],[México]],'CALENDARIO INGRESOS'!$G:$G,">="&$A22,'CALENDARIO INGRESOS'!$G:$G,"<="&EOMONTH($A22,0)),0) -> 24720.63 | F22: =IFERROR(SUMIFS('CALENDARIO INGRESOS'!$I:$I,'CALENDARIO INGRESOS'!$C:$C,Tabla814[[#Headers],[Colombia]],'CALENDARIO INGRESOS'!$G:$G,">="&$A22,'CALENDARIO INGRESOS'!$G:$G,"<="&EOMONTH($A22,0)),0) -> 23061 | G22: =IFERROR(SUMIFS('CALENDARIO INGRESOS'!$I:$I,'CALENDARIO INGRESOS'!$C:$C,Tabla814[[#Headers],[República Dominicana]],'CALENDARIO INGRESOS'!$G:$G,">="&$A22,'CALENDARIO INGRESOS'!$G:$G,"<="&EOMONTH($A22,0)),0) -> 2600 | H22: =IFERROR(SUMIFS('CALENDARIO INGRESOS'!$I:$I,'CALENDARIO INGRESOS'!$C:$C,Tabla814[[#Headers],[Perú]],'CALENDARIO INGRESOS'!$G:$G,">="&$A22,'CALENDARIO INGRESOS'!$G:$G,"<="&EOMONTH($A22,0)),0) -> 12600 | I22: =IFERROR(SUMIFS('CALENDARIO INGRESOS'!$I:$I,'CALENDARIO INGRESOS'!$C:$C,Tabla814[[#Headers],[Paraguay]],'CALENDARIO INGRESOS'!$G:$G,">="&$A22,'CALENDARIO INGRESOS'!$G:$G,"<="&EOMONTH($A22,0)),0) -> 0 | J22: =IFERROR(SUMIFS('CALENDARIO INGRESOS'!$I:$I,'CALENDARIO INGRESOS'!$C:$C,Tabla814[[#Headers],[Honduras]],'CALENDARIO INGRESOS'!$G:$G,">="&$A22,'CALENDARIO INGRESOS'!$G:$G,"<="&EOMONTH($A22,0)),0) -> 1570 | K22: =IFERROR(SUMIFS('CALENDARIO INGRESOS'!$I:$I,'CALENDARIO INGRESOS'!$C:$C,Tabla814[[#Headers],[Bolivia]],'CALENDARIO INGRESOS'!$G:$G,">="&$A22,'CALENDARIO INGRESOS'!$G:$G,"<="&EOMONTH($A22,0)),0) -> 500 | L22: =IFERROR(SUMIFS('CALENDARIO INGRESOS'!$I:$I,'CALENDARIO INGRESOS'!$C:$C,Tabla814[[#Headers],[Argentina]],'CALENDARIO INGRESOS'!$G:$G,">="&$A22,'CALENDARIO INGRESOS'!$G:$G,"<="&EOMONTH($A22,0)),0) -> 2200 | M22: =IFERROR(SUMIFS('CALENDARIO INGRESOS'!$I:$I,'CALENDARIO INGRESOS'!$C:$C,Tabla814[[#Headers],[Guatemala]],'CALENDARIO INGRESOS'!$G:$G,">="&$A22,'CALENDARIO INGRESOS'!$G:$G,"<="&EOMONTH($A22,0)),0) -> 700 | N22: =IFERROR(SUMIFS('CALENDARIO INGRESOS'!$I:$I,'CALENDARIO INGRESOS'!$C:$C,Tabla814[[#Headers],[Venezuela]],'CALENDARIO INGRESOS'!$G:$G,">="&$A22,'CALENDARIO INGRESOS'!$G:$G,"<="&EOMONTH($A22,0)),0) -> 2000 | O22: =IFERROR(SUMIFS('CALENDARIO INGRESOS'!$I:$I,'CALENDARIO INGRESOS'!$C:$C,Tabla814[[#Headers],[Uruguay]],'CALENDARIO INGRESOS'!$G:$G,">="&$A22,'CALENDARIO INGRESOS'!$G:$G,"<="&EOMONTH($A22,0)),0) -> 0 | P22: =IFERROR(SUMIFS('CALENDARIO INGRESOS'!$I:$I,'CALENDARIO INGRESOS'!$C:$C,Tabla814[[#Headers],[Nicaragua]],'CALENDARIO INGRESOS'!$G:$G,">="&$A22,'CALENDARIO INGRESOS'!$G:$G,"<="&EOMONTH($A22,0)),0) -> 0 | Q22: =+SUM(Tabla814[[#This Row],[El Salvador]:[Nicaragua]]) -> 101776.63
A23: 46174 | B23: =IFERROR(SUMIFS('CALENDARIO INGRESOS'!$I:$I,'CALENDARIO INGRESOS'!$C:$C,Tabla814[[#Headers],[El Salvador]],'CALENDARIO INGRESOS'!$G:$G,">="&$A23,'CALENDARIO INGRESOS'!$G:$G,"<="&EOMONTH($A23,0)),0) -> 16850 | C23: =IFERROR(SUMIFS('CALENDARIO INGRESOS'!$I:$I,'CALENDARIO INGRESOS'!$C:$C,Tabla814[[#Headers],[Chile]],'CALENDARIO INGRESOS'!$G:$G,">="&$A23,'CALENDARIO INGRESOS'!$G:$G,"<="&EOMONTH($A23,0)),0) -> 14700 | D23: =IFERROR(SUMIFS('CALENDARIO INGRESOS'!$I:$I,'CALENDARIO INGRESOS'!$C:$C,Tabla814[[#Headers],[Ecuador]],'CALENDARIO INGRESOS'!$G:$G,">="&$A23,'CALENDARIO INGRESOS'!$G:$G,"<="&EOMONTH($A23,0)),0) -> 21245 | E23: =IFERROR(SUMIFS('CALENDARIO INGRESOS'!$I:$I,'CALENDARIO INGRESOS'!$C:$C,Tabla814[[#Headers],[México]],'CALENDARIO INGRESOS'!$G:$G,">="&$A23,'CALENDARIO INGRESOS'!$G:$G,"<="&EOMONTH($A23,0)),0) -> 30970.63 | F23: =IFERROR(SUMIFS('CALENDARIO INGRESOS'!$I:$I,'CALENDARIO INGRESOS'!$C:$C,Tabla814[[#Headers],[Colombia]],'CALENDARIO INGRESOS'!$G:$G,">="&$A23,'CALENDARIO INGRESOS'!$G:$G,"<="&EOMONTH($A23,0)),0) -> 9061 | G23: =IFERROR(SUMIFS('CALENDARIO INGRESOS'!$I:$I,'CALENDARIO INGRESOS'!$C:$C,Tabla814[[#Headers],[República Dominicana]],'CALENDARIO INGRESOS'!$G:$G,">="&$A23,'CALENDARIO INGRESOS'!$G:$G,"<="&EOMONTH($A23,0)),0) -> 1600 | H23: =IFERROR(SUMIFS('CALENDARIO INGRESOS'!$I:$I,'CALENDARIO INGRESOS'!$C:$C,Tabla814[[#Headers],[Perú]],'CALENDARIO INGRESOS'!$G:$G,">="&$A23,'CALENDARIO INGRESOS'!$G:$G,"<="&EOMONTH($A23,0)),0) -> 8600 | I23: =IFERROR(SUMIFS('CALENDARIO INGRESOS'!$I:$I,'CALENDARIO INGRESOS'!$C:$C,Tabla814[[#Headers],[Paraguay]],'CALENDARIO INGRESOS'!$G:$G,">="&$A23,'CALENDARIO INGRESOS'!$G:$G,"<="&EOMONTH($A23,0)),0) -> 0 | J23: =IFERROR(SUMIFS('CALENDARIO INGRESOS'!$I:$I,'CALENDARIO INGRESOS'!$C:$C,Tabla814[[#Headers],[Honduras]],'CALENDARIO INGRESOS'!$G:$G,">="&$A23,'CALENDARIO INGRESOS'!$G:$G,"<="&EOMONTH($A23,0)),0) -> 0 | K23: =IFERROR(SUMIFS('CALENDARIO INGRESOS'!$I:$I,'CALENDARIO INGRESOS'!$C:$C,Tabla814[[#Headers],[Bolivia]],'CALENDARIO INGRESOS'!$G:$G,">="&$A23,'CALENDARIO INGRESOS'!$G:$G,"<="&EOMONTH($A23,0)),0) -> 500 | L23: =IFERROR(SUMIFS('CALENDARIO INGRESOS'!$I:$I,'CALENDARIO INGRESOS'!$C:$C,Tabla814[[#Headers],[Argentina]],'CALENDARIO INGRESOS'!$G:$G,">="&$A23,'CALENDARIO INGRESOS'!$G:$G,"<="&EOMONTH($A23,0)),0) -> 2200 | M23: =IFERROR(SUMIFS('CALENDARIO INGRESOS'!$I:$I,'CALENDARIO INGRESOS'!$C:$C,Tabla814[[#Headers],[Guatemala]],'CALENDARIO INGRESOS'!$G:$G,">="&$A23,'CALENDARIO INGRESOS'!$G:$G,"<="&EOMONTH($A23,0)),0) -> 700 | N23: =IFERROR(SUMIFS('CALENDARIO INGRESOS'!$I:$I,'CALENDARIO INGRESOS'!$C:$C,Tabla814[[#Headers],[Venezuela]],'CALENDARIO INGRESOS'!$G:$G,">="&$A23,'CALENDARIO INGRESOS'!$G:$G,"<="&EOMONTH($A23,0)),0) -> 2000 | O23: =IFERROR(SUMIFS('CALENDARIO INGRESOS'!$I:$I,'CALENDARIO INGRESOS'!$C:$C,Tabla814[[#Headers],[Uruguay]],'CALENDARIO INGRESOS'!$G:$G,">="&$A23,'CALENDARIO INGRESOS'!$G:$G,"<="&EOMONTH($A23,0)),0) -> 0 | P23: =IFERROR(SUMIFS('CALENDARIO INGRESOS'!$I:$I,'CALENDARIO INGRESOS'!$C:$C,Tabla814[[#Headers],[Nicaragua]],'CALENDARIO INGRESOS'!$G:$G,">="&$A23,'CALENDARIO INGRESOS'!$G:$G,"<="&EOMONTH($A23,0)),0) -> 0 | Q23: =+SUM(Tabla814[[#This Row],[El Salvador]:[Nicaragua]]) -> 108426.63
A24: 46204 | B24: =IFERROR(SUMIFS('CALENDARIO INGRESOS'!$I:$I,'CALENDARIO INGRESOS'!$C:$C,Tabla814[[#Headers],[El Salvador]],'CALENDARIO INGRESOS'!$G:$G,">="&$A24,'CALENDARIO INGRESOS'!$G:$G,"<="&EOMONTH($A24,0)),0) -> 850 | C24: =IFERROR(SUMIFS('CALENDARIO INGRESOS'!$I:$I,'CALENDARIO INGRESOS'!$C:$C,Tabla814[[#Headers],[Chile]],'CALENDARIO INGRESOS'!$G:$G,">="&$A24,'CALENDARIO INGRESOS'!$G:$G,"<="&EOMONTH($A24,0)),0) -> 17700 | D24: =IFERROR(SUMIFS('CALENDARIO INGRESOS'!$I:$I,'CALENDARIO INGRESOS'!$C:$C,Tabla814[[#Headers],[Ecuador]],'CALENDARIO INGRESOS'!$G:$G,">="&$A24,'CALENDARIO INGRESOS'!$G:$G,"<="&EOMONTH($A24,0)),0) -> 23475 | E24: =IFERROR(SUMIFS('CALENDARIO INGRESOS'!$I:$I,'CALENDARIO INGRESOS'!$C:$C,Tabla814[[#Headers],[México]],'CALENDARIO INGRESOS'!$G:$G,">="&$A24,'CALENDARIO INGRESOS'!$G:$G,"<="&EOMONTH($A24,0)),0) -> 20534 | F24: =IFERROR(SUMIFS('CALENDARIO INGRESOS'!$I:$I,'CALENDARIO INGRESOS'!$C:$C,Tabla814[[#Headers],[Colombia]],'CALENDARIO INGRESOS'!$G:$G,">="&$A24,'CALENDARIO INGRESOS'!$G:$G,"<="&EOMONTH($A24,0)),0) -> 8261 | G24: =IFERROR(SUMIFS('CALENDARIO INGRESOS'!$I:$I,'CALENDARIO INGRESOS'!$C:$C,Tabla814[[#Headers],[República Dominicana]],'CALENDARIO INGRESOS'!$G:$G,">="&$A24,'CALENDARIO INGRESOS'!$G:$G,"<="&EOMONTH($A24,0)),0) -> 5800 | H24: =IFERROR(SUMIFS('CALENDARIO INGRESOS'!$I:$I,'CALENDARIO INGRESOS'!$C:$C,Tabla814[[#Headers],[Perú]],'CALENDARIO INGRESOS'!$G:$G,">="&$A24,'CALENDARIO INGRESOS'!$G:$G,"<="&EOMONTH($A24,0)),0) -> 8250 | I24: =IFERROR(SUMIFS('CALENDARIO INGRESOS'!$I:$I,'CALENDARIO INGRESOS'!$C:$C,Tabla814[[#Headers],[Paraguay]],'CALENDARIO INGRESOS'!$G:$G,">="&$A24,'CALENDARIO INGRESOS'!$G:$G,"<="&EOMONTH($A24,0)),0) -> 0 | J24: =IFERROR(SUMIFS('CALENDARIO INGRESOS'!$I:$I,'CALENDARIO INGRESOS'!$C:$C,Tabla814[[#Headers],[Honduras]],'CALENDARIO INGRESOS'!$G:$G,">="&$A24,'CALENDARIO INGRESOS'!$G:$G,"<="&EOMONTH($A24,0)),0) -> 0 | K24: =IFERROR(SUMIFS('CALENDARIO INGRESOS'!$I:$I,'CALENDARIO INGRESOS'!$C:$C,Tabla814[[#Headers],[Bolivia]],'CALENDARIO INGRESOS'!$G:$G,">="&$A24,'CALENDARIO INGRESOS'!$G:$G,"<="&EOMONTH($A24,0)),0) -> 500 | L24: =IFERROR(SUMIFS('CALENDARIO INGRESOS'!$I:$I,'CALENDARIO INGRESOS'!$C:$C,Tabla814[[#Headers],[Argentina]],'CALENDARIO INGRESOS'!$G:$G,">="&$A24,'CALENDARIO INGRESOS'!$G:$G,"<="&EOMONTH($A24,0)),0) -> 2200 | M24: =IFERROR(SUMIFS('CALENDARIO INGRESOS'!$I:$I,'CALENDARIO INGRESOS'!$C:$C,Tabla814[[#Headers],[Guatemala]],'CALENDARIO INGRESOS'!$G:$G,">="&$A24,'CALENDARIO INGRESOS'!$G:$G,"<="&EOMONTH($A24,0)),0) -> 700 | N24: =IFERROR(SUMIFS('CALENDARIO INGRESOS'!$I:$I,'CALENDARIO INGRESOS'!$C:$C,Tabla814[[#Headers],[Venezuela]],'CALENDARIO INGRESOS'!$G:$G,">="&$A24,'CALENDARIO INGRESOS'!$G:$G,"<="&EOMONTH($A24,0)),0) -> 2000 | O24: =IFERROR(SUMIFS('CALENDARIO INGRESOS'!$I:$I,'CALENDARIO INGRESOS'!$C:$C,Tabla814[[#Headers],[Uruguay]],'CALENDARIO INGRESOS'!$G:$G,">="&$A24,'CALENDARIO INGRESOS'!$G:$G,"<="&EOMONTH($A24,0)),0) -> 0 | P24: =IFERROR(SUMIFS('CALENDARIO INGRESOS'!$I:$I,'CALENDARIO INGRESOS'!$C:$C,Tabla814[[#Headers],[Nicaragua]],'CALENDARIO INGRESOS'!$G:$G,">="&$A24,'CALENDARIO INGRESOS'!$G:$G,"<="&EOMONTH($A24,0)),0) -> 0 | Q24: =+SUM(Tabla814[[#This Row],[El Salvador]:[Nicaragua]]) -> 90270
A25: 46235 | B25: =IFERROR(SUMIFS('CALENDARIO INGRESOS'!$I:$I,'CALENDARIO INGRESOS'!$C:$C,Tabla814[[#Headers],[El Salvador]],'CALENDARIO INGRESOS'!$G:$G,">="&$A25,'CALENDARIO INGRESOS'!$G:$G,"<="&EOMONTH($A25,0)),0) -> 850 | C25: =IFERROR(SUMIFS('CALENDARIO INGRESOS'!$I:$I,'CALENDARIO INGRESOS'!$C:$C,Tabla814[[#Headers],[Chile]],'CALENDARIO INGRESOS'!$G:$G,">="&$A25,'CALENDARIO INGRESOS'!$G:$G,"<="&EOMONTH($A25,0)),0) -> 12100 | D25: =IFERROR(SUMIFS('CALENDARIO INGRESOS'!$I:$I,'CALENDARIO INGRESOS'!$C:$C,Tabla814[[#Headers],[Ecuador]],'CALENDARIO INGRESOS'!$G:$G,">="&$A25,'CALENDARIO INGRESOS'!$G:$G,"<="&EOMONTH($A25,0)),0) -> 13100 | E25: =IFERROR(SUMIFS('CALENDARIO INGRESOS'!$I:$I,'CALENDARIO INGRESOS'!$C:$C,Tabla814[[#Headers],[México]],'CALENDARIO INGRESOS'!$G:$G,">="&$A25,'CALENDARIO INGRESOS'!$G:$G,"<="&EOMONTH($A25,0)),0) -> 18534 | F25: =IFERROR(SUMIFS('CALENDARIO INGRESOS'!$I:$I,'CALENDARIO INGRESOS'!$C:$C,Tabla814[[#Headers],[Colombia]],'CALENDARIO INGRESOS'!$G:$G,">="&$A25,'CALENDARIO INGRESOS'!$G:$G,"<="&EOMONTH($A25,0)),0) -> 10511 | G25: =IFERROR(SUMIFS('CALENDARIO INGRESOS'!$I:$I,'CALENDARIO INGRESOS'!$C:$C,Tabla814[[#Headers],[República Dominicana]],'CALENDARIO INGRESOS'!$G:$G,">="&$A25,'CALENDARIO INGRESOS'!$G:$G,"<="&EOMONTH($A25,0)),0) -> 1000 | H25: =IFERROR(SUMIFS('CALENDARIO INGRESOS'!$I:$I,'CALENDARIO INGRESOS'!$C:$C,Tabla814[[#Headers],[Perú]],'CALENDARIO INGRESOS'!$G:$G,">="&$A25,'CALENDARIO INGRESOS'!$G:$G,"<="&EOMONTH($A25,0)),0) -> 10216 | I25: =IFERROR(SUMIFS('CALENDARIO INGRESOS'!$I:$I,'CALENDARIO INGRESOS'!$C:$C,Tabla814[[#Headers],[Paraguay]],'CALENDARIO INGRESOS'!$G:$G,">="&$A25,'CALENDARIO INGRESOS'!$G:$G,"<="&EOMONTH($A25,0)),0) -> 0 | J25: =IFERROR(SUMIFS('CALENDARIO INGRESOS'!$I:$I,'CALENDARIO INGRESOS'!$C:$C,Tabla814[[#Headers],[Honduras]],'CALENDARIO INGRESOS'!$G:$G,">="&$A25,'CALENDARIO INGRESOS'!$G:$G,"<="&EOMONTH($A25,0)),0) -> 0 | K25: =IFERROR(SUMIFS('CALENDARIO INGRESOS'!$I:$I,'CALENDARIO INGRESOS'!$C:$C,Tabla814[[#Headers],[Bolivia]],'CALENDARIO INGRESOS'!$G:$G,">="&$A25,'CALENDARIO INGRESOS'!$G:$G,"<="&EOMONTH($A25,0)),0) -> 500 | L25: =IFERROR(SUMIFS('CALENDARIO INGRESOS'!$I:$I,'CALENDARIO INGRESOS'!$C:$C,Tabla814[[#Headers],[Argentina]],'CALENDARIO INGRESOS'!$G:$G,">="&$A25,'CALENDARIO INGRESOS'!$G:$G,"<="&EOMONTH($A25,0)),0) -> 2200 | M25: =IFERROR(SUMIFS('CALENDARIO INGRESOS'!$I:$I,'CALENDARIO INGRESOS'!$C:$C,Tabla814[[#Headers],[Guatemala]],'CALENDARIO INGRESOS'!$G:$G,">="&$A25,'CALENDARIO INGRESOS'!$G:$G,"<="&EOMONTH($A25,0)),0) -> 700 | N25: =IFERROR(SUMIFS('CALENDARIO INGRESOS'!$I:$I,'CALENDARIO INGRESOS'!$C:$C,Tabla814[[#Headers],[Venezuela]],'CALENDARIO INGRESOS'!$G:$G,">="&$A25,'CALENDARIO INGRESOS'!$G:$G,"<="&EOMONTH($A25,0)),0) -> 2000 | O25: =IFERROR(SUMIFS('CALENDARIO INGRESOS'!$I:$I,'CALENDARIO INGRESOS'!$C:$C,Tabla814[[#Headers],[Uruguay]],'CALENDARIO INGRESOS'!$G:$G,">="&$A25,'CALENDARIO INGRESOS'!$G:$G,"<="&EOMONTH($A25,0)),0) -> 0 | P25: =IFERROR(SUMIFS('CALENDARIO INGRESOS'!$I:$I,'CALENDARIO INGRESOS'!$C:$C,Tabla814[[#Headers],[Nicaragua]],'CALENDARIO INGRESOS'!$G:$G,">="&$A25,'CALENDARIO INGRESOS'!$G:$G,"<="&EOMONTH($A25,0)),0) -> 0 | Q25: =+SUM(Tabla814[[#This Row],[El Salvador]:[Nicaragua]]) -> 71711
A26: 46266 | B26: =IFERROR(SUMIFS('CALENDARIO INGRESOS'!$I:$I,'CALENDARIO INGRESOS'!$C:$C,Tabla814[[#Headers],[El Salvador]],'CALENDARIO INGRESOS'!$G:$G,">="&$A26,'CALENDARIO INGRESOS'!$G:$G,"<="&EOMONTH($A26,0)),0) -> 1850 | C26: =IFERROR(SUMIFS('CALENDARIO INGRESOS'!$I:$I,'CALENDARIO INGRESOS'!$C:$C,Tabla814[[#Headers],[Chile]],'CALENDARIO INGRESOS'!$G:$G,">="&$A26,'CALENDARIO INGRESOS'!$G:$G,"<="&EOMONTH($A26,0)),0) -> 12700 | D26: =IFERROR(SUMIFS('CALENDARIO INGRESOS'!$I:$I,'CALENDARIO INGRESOS'!$C:$C,Tabla814[[#Headers],[Ecuador]],'CALENDARIO INGRESOS'!$G:$G,">="&$A26,'CALENDARIO INGRESOS'!$G:$G,"<="&EOMONTH($A26,0)),0) -> 12900 | E26: =IFERROR(SUMIFS('CALENDARIO INGRESOS'!$I:$I,'CALENDARIO INGRESOS'!$C:$C,Tabla814[[#Headers],[México]],'CALENDARIO INGRESOS'!$G:$G,">="&$A26,'CALENDARIO INGRESOS'!$G:$G,"<="&EOMONTH($A26,0)),0) -> 17634 | F26: =IFERROR(SUMIFS('CALENDARIO INGRESOS'!$I:$I,'CALENDARIO INGRESOS'!$C:$C,Tabla814[[#Headers],[Colombia]],'CALENDARIO INGRESOS'!$G:$G,">="&$A26,'CALENDARIO INGRESOS'!$G:$G,"<="&EOMONTH($A26,0)),0) -> 5961 | G26: =IFERROR(SUMIFS('CALENDARIO INGRESOS'!$I:$I,'CALENDARIO INGRESOS'!$C:$C,Tabla814[[#Headers],[República Dominicana]],'CALENDARIO INGRESOS'!$G:$G,">="&$A26,'CALENDARIO INGRESOS'!$G:$G,"<="&EOMONTH($A26,0)),0) -> 1000 | H26: =IFERROR(SUMIFS('CALENDARIO INGRESOS'!$I:$I,'CALENDARIO INGRESOS'!$C:$C,Tabla814[[#Headers],[Perú]],'CALENDARIO INGRESOS'!$G:$G,">="&$A26,'CALENDARIO INGRESOS'!$G:$G,"<="&EOMONTH($A26,0)),0) -> 4350 | I26: =IFERROR(SUMIFS('CALENDARIO INGRESOS'!$I:$I,'CALENDARIO INGRESOS'!$C:$C,Tabla814[[#Headers],[Paraguay]],'CALENDARIO INGRESOS'!$G:$G,">="&$A26,'CALENDARIO INGRESOS'!$G:$G,"<="&EOMONTH($A26,0)),0) -> 0 | J26: =IFERROR(SUMIFS('CALENDARIO INGRESOS'!$I:$I,'CALENDARIO INGRESOS'!$C:$C,Tabla814[[#Headers],[Honduras]],'CALENDARIO INGRESOS'!$G:$G,">="&$A26,'CALENDARIO INGRESOS'!$G:$G,"<="&EOMONTH($A26,0)),0) -> 1187 | K26: =IFERROR(SUMIFS('CALENDARIO INGRESOS'!$I:$I,'CALENDARIO INGRESOS'!$C:$C,Tabla814[[#Headers],[Bolivia]],'CALENDARIO INGRESOS'!$G:$G,">="&$A26,'CALENDARIO INGRESOS'!$G:$G,"<="&EOMONTH($A26,0)),0) -> 500 | L26: =IFERROR(SUMIFS('CALENDARIO INGRESOS'!$I:$I,'CALENDARIO INGRESOS'!$C:$C,Tabla814[[#Headers],[Argentina]],'CALENDARIO INGRESOS'!$G:$G,">="&$A26,'CALENDARIO INGRESOS'!$G:$G,"<="&EOMONTH($A26,0)),0) -> 1200 | M26: =IFERROR(SUMIFS('CALENDARIO INGRESOS'!$I:$I,'CALENDARIO INGRESOS'!$C:$C,Tabla814[[#Headers],[Guatemala]],'CALENDARIO INGRESOS'!$G:$G,">="&$A26,'CALENDARIO INGRESOS'!$G:$G,"<="&EOMONTH($A26,0)),0) -> 700 | N26: =IFERROR(SUMIFS('CALENDARIO INGRESOS'!$I:$I,'CALENDARIO INGRESOS'!$C:$C,Tabla814[[#Headers],[Venezuela]],'CALENDARIO INGRESOS'!$G:$G,">="&$A26,'CALENDARIO INGRESOS'!$G:$G,"<="&EOMONTH($A26,0)),0) -> 2000 | O26: =IFERROR(SUMIFS('CALENDARIO INGRESOS'!$I:$I,'CALENDARIO INGRESOS'!$C:$C,Tabla814[[#Headers],[Uruguay]],'CALENDARIO INGRESOS'!$G:$G,">="&$A26,'CALENDARIO INGRESOS'!$G:$G,"<="&EOMONTH($A26,0)),0) -> 0 | P26: =IFERROR(SUMIFS('CALENDARIO INGRESOS'!$I:$I,'CALENDARIO INGRESOS'!$C:$C,Tabla814[[#Headers],[Nicaragua]],'CALENDARIO INGRESOS'!$G:$G,">="&$A26,'CALENDARIO INGRESOS'!$G:$G,"<="&EOMONTH($A26,0)),0) -> 0 | Q26: =+SUM(Tabla814[[#This Row],[El Salvador]:[Nicaragua]]) -> 61982
A27: 46296 | B27: =IFERROR(SUMIFS('CALENDARIO INGRESOS'!$I:$I,'CALENDARIO INGRESOS'!$C:$C,Tabla814[[#Headers],[El Salvador]],'CALENDARIO INGRESOS'!$G:$G,">="&$A27,'CALENDARIO INGRESOS'!$G:$G,"<="&EOMONTH($A27,0)),0) -> 1850 | C27: =IFERROR(SUMIFS('CALENDARIO INGRESOS'!$I:$I,'CALENDARIO INGRESOS'!$C:$C,Tabla814[[#Headers],[Chile]],'CALENDARIO INGRESOS'!$G:$G,">="&$A27,'CALENDARIO INGRESOS'!$G:$G,"<="&EOMONTH($A27,0)),0) -> 11850 | D27: =IFERROR(SUMIFS('CALENDARIO INGRESOS'!$I:$I,'CALENDARIO INGRESOS'!$C:$C,Tabla814[[#Headers],[Ecuador]],'CALENDARIO INGRESOS'!$G:$G,">="&$A27,'CALENDARIO INGRESOS'!$G:$G,"<="&EOMONTH($A27,0)),0) -> 16150 | E27: =IFERROR(SUMIFS('CALENDARIO INGRESOS'!$I:$I,'CALENDARIO INGRESOS'!$C:$C,Tabla814[[#Headers],[México]],'CALENDARIO INGRESOS'!$G:$G,">="&$A27,'CALENDARIO INGRESOS'!$G:$G,"<="&EOMONTH($A27,0)),0) -> 16634 | F27: =IFERROR(SUMIFS('CALENDARIO INGRESOS'!$I:$I,'CALENDARIO INGRESOS'!$C:$C,Tabla814[[#Headers],[Colombia]],'CALENDARIO INGRESOS'!$G:$G,">="&$A27,'CALENDARIO INGRESOS'!$G:$G,"<="&EOMONTH($A27,0)),0) -> 5461 | G27: =IFERROR(SUMIFS('CALENDARIO INGRESOS'!$I:$I,'CALENDARIO INGRESOS'!$C:$C,Tabla814[[#Headers],[República Dominicana]],'CALENDARIO INGRESOS'!$G:$G,">="&$A27,'CALENDARIO INGRESOS'!$G:$G,"<="&EOMONTH($A27,0)),0) -> 1000 | H27: =IFERROR(SUMIFS('CALENDARIO INGRESOS'!$I:$I,'CALENDARIO INGRESOS'!$C:$C,Tabla814[[#Headers],[Perú]],'CALENDARIO INGRESOS'!$G:$G,">="&$A27,'CALENDARIO INGRESOS'!$G:$G,"<="&EOMONTH($A27,0)),0) -> 5350 | I27: =IFERROR(SUMIFS('CALENDARIO INGRESOS'!$I:$I,'CALENDARIO INGRESOS'!$C:$C,Tabla814[[#Headers],[Paraguay]],'CALENDARIO INGRESOS'!$G:$G,">="&$A27,'CALENDARIO INGRESOS'!$G:$G,"<="&EOMONTH($A27,0)),0) -> 0 | J27: =IFERROR(SUMIFS('CALENDARIO INGRESOS'!$I:$I,'CALENDARIO INGRESOS'!$C:$C,Tabla814[[#Headers],[Honduras]],'CALENDARIO INGRESOS'!$G:$G,">="&$A27,'CALENDARIO INGRESOS'!$G:$G,"<="&EOMONTH($A27,0)),0) -> 2187 | K27: =IFERROR(SUMIFS('CALENDARIO INGRESOS'!$I:$I,'CALENDARIO INGRESOS'!$C:$C,Tabla814[[#Headers],[Bolivia]],'CALENDARIO INGRESOS'!$G:$G,">="&$A27,'CALENDARIO INGRESOS'!$G:$G,"<="&EOMONTH($A27,0)),0) -> 500 | L27: =IFERROR(SUMIFS('CALENDARIO INGRESOS'!$I:$I,'CALENDARIO INGRESOS'!$C:$C,Tabla814[[#Headers],[Argentina]],'CALENDARIO INGRESOS'!$G:$G,">="&$A27,'CALENDARIO INGRESOS'!$G:$G,"<="&EOMONTH($A27,0)),0) -> 1200 | M27: =IFERROR(SUMIFS('CALENDARIO INGRESOS'!$I:$I,'CALENDARIO INGRESOS'!$C:$C,Tabla814[[#Headers],[Guatemala]],'CALENDARIO INGRESOS'!$G:$G,">="&$A27,'CALENDARIO INGRESOS'!$G:$G,"<="&EOMONTH($A27,0)),0) -> 1576 | N27: =IFERROR(SUMIFS('CALENDARIO INGRESOS'!$I:$I,'CALENDARIO INGRESOS'!$C:$C,Tabla814[[#Headers],[Venezuela]],'CALENDARIO INGRESOS'!$G:$G,">="&$A27,'CALENDARIO INGRESOS'!$G:$G,"<="&EOMONTH($A27,0)),0) -> 6000 | O27: =IFERROR(SUMIFS('CALENDARIO INGRESOS'!$I:$I,'CALENDARIO INGRESOS'!$C:$C,Tabla814[[#Headers],[Uruguay]],'CALENDARIO INGRESOS'!$G:$G,">="&$A27,'CALENDARIO INGRESOS'!$G:$G,"<="&EOMONTH($A27,0)),0) -> 0 | P27: =IFERROR(SUMIFS('CALENDARIO INGRESOS'!$I:$I,'CALENDARIO INGRESOS'!$C:$C,Tabla814[[#Headers],[Nicaragua]],'CALENDARIO INGRESOS'!$G:$G,">="&$A27,'CALENDARIO INGRESOS'!$G:$G,"<="&EOMONTH($A27,0)),0) -> 0 | Q27: =+SUM(Tabla814[[#This Row],[El Salvador]:[Nicaragua]]) -> 69758
A28: 46327 | B28: =IFERROR(SUMIFS('CALENDARIO INGRESOS'!$I:$I,'CALENDARIO INGRESOS'!$C:$C,Tabla814[[#Headers],[El Salvador]],'CALENDARIO INGRESOS'!$G:$G,">="&$A28,'CALENDARIO INGRESOS'!$G:$G,"<="&EOMONTH($A28,0)),0) -> 2950 | C28: =IFERROR(SUMIFS('CALENDARIO INGRESOS'!$I:$I,'CALENDARIO INGRESOS'!$C:$C,Tabla814[[#Headers],[Chile]],'CALENDARIO INGRESOS'!$G:$G,">="&$A28,'CALENDARIO INGRESOS'!$G:$G,"<="&EOMONTH($A28,0)),0) -> 16079 | D28: =IFERROR(SUMIFS('CALENDARIO INGRESOS'!$I:$I,'CALENDARIO INGRESOS'!$C:$C,Tabla814[[#Headers],[Ecuador]],'CALENDARIO INGRESOS'!$G:$G,">="&$A28,'CALENDARIO INGRESOS'!$G:$G,"<="&EOMONTH($A28,0)),0) -> 17400 | E28: =IFERROR(SUMIFS('CALENDARIO INGRESOS'!$I:$I,'CALENDARIO INGRESOS'!$C:$C,Tabla814[[#Headers],[México]],'CALENDARIO INGRESOS'!$G:$G,">="&$A28,'CALENDARIO INGRESOS'!$G:$G,"<="&EOMONTH($A28,0)),0) -> 15434 | F28: =IFERROR(SUMIFS('CALENDARIO INGRESOS'!$I:$I,'CALENDARIO INGRESOS'!$C:$C,Tabla814[[#Headers],[Colombia]],'CALENDARIO INGRESOS'!$G:$G,">="&$A28,'CALENDARIO INGRESOS'!$G:$G,"<="&EOMONTH($A28,0)),0) -> 5200 | G28: =IFERROR(SUMIFS('CALENDARIO INGRESOS'!$I:$I,'CALENDARIO INGRESOS'!$C:$C,Tabla814[[#Headers],[República Dominicana]],'CALENDARIO INGRESOS'!$G:$G,">="&$A28,'CALENDARIO INGRESOS'!$G:$G,"<="&EOMONTH($A28,0)),0) -> 2000 | H28: =IFERROR(SUMIFS('CALENDARIO INGRESOS'!$I:$I,'CALENDARIO INGRESOS'!$C:$C,Tabla814[[#Headers],[Perú]],'CALENDARIO INGRESOS'!$G:$G,">="&$A28,'CALENDARIO INGRESOS'!$G:$G,"<="&EOMONTH($A28,0)),0) -> 6350 | I28: =IFERROR(SUMIFS('CALENDARIO INGRESOS'!$I:$I,'CALENDARIO INGRESOS'!$C:$C,Tabla814[[#Headers],[Paraguay]],'CALENDARIO INGRESOS'!$G:$G,">="&$A28,'CALENDARIO INGRESOS'!$G:$G,"<="&EOMONTH($A28,0)),0) -> 0 | J28: =IFERROR(SUMIFS('CALENDARIO INGRESOS'!$I:$I,'CALENDARIO INGRESOS'!$C:$C,Tabla814[[#Headers],[Honduras]],'CALENDARIO INGRESOS'!$G:$G,">="&$A28,'CALENDARIO INGRESOS'!$G:$G,"<="&EOMONTH($A28,0)),0) -> 2187 | K28: =IFERROR(SUMIFS('CALENDARIO INGRESOS'!$I:$I,'CALENDARIO INGRESOS'!$C:$C,Tabla814[[#Headers],[Bolivia]],'CALENDARIO INGRESOS'!$G:$G,">="&$A28,'CALENDARIO INGRESOS'!$G:$G,"<="&EOMONTH($A28,0)),0) -> 500 | L28: =IFERROR(SUMIFS('CALENDARIO INGRESOS'!$I:$I,'CALENDARIO INGRESOS'!$C:$C,Tabla814[[#Headers],[Argentina]],'CALENDARIO INGRESOS'!$G:$G,">="&$A28,'CALENDARIO INGRESOS'!$G:$G,"<="&EOMONTH($A28,0)),0) -> 1200 | M28: =IFERROR(SUMIFS('CALENDARIO INGRESOS'!$I:$I,'CALENDARIO INGRESOS'!$C:$C,Tabla814[[#Headers],[Guatemala]],'CALENDARIO INGRESOS'!$G:$G,">="&$A28,'CALENDARIO INGRESOS'!$G:$G,"<="&EOMONTH($A28,0)),0) -> 1600 | N28: =IFERROR(SUMIFS('CALENDARIO INGRESOS'!$I:$I,'CALENDARIO INGRESOS'!$C:$C,Tabla814[[#Headers],[Venezuela]],'CALENDARIO INGRESOS'!$G:$G,">="&$A28,'CALENDARIO INGRESOS'!$G:$G,"<="&EOMONTH($A28,0)),0) -> 1000 | O28: =IFERROR(SUMIFS('CALENDARIO INGRESOS'!$I:$I,'CALENDARIO INGRESOS'!$C:$C,Tabla814[[#Headers],[Uruguay]],'CALENDARIO INGRESOS'!$G:$G,">="&$A28,'CALENDARIO INGRESOS'!$G:$G,"<="&EOMONTH($A28,0)),0) -> 0 | P28: =IFERROR(SUMIFS('CALENDARIO INGRESOS'!$I:$I,'CALENDARIO INGRESOS'!$C:$C,Tabla814[[#Headers],[Nicaragua]],'CALENDARIO INGRESOS'!$G:$G,">="&$A28,'CALENDARIO INGRESOS'!$G:$G,"<="&EOMONTH($A28,0)),0) -> 0 | Q28: =+SUM(Tabla814[[#This Row],[El Salvador]:[Nicaragua]]) -> 71900
A29: 46357 | B29: =IFERROR(SUMIFS('CALENDARIO INGRESOS'!$I:$I,'CALENDARIO INGRESOS'!$C:$C,Tabla814[[#Headers],[El Salvador]],'CALENDARIO INGRESOS'!$G:$G,">="&$A29,'CALENDARIO INGRESOS'!$G:$G,"<="&EOMONTH($A29,0)),0) -> 2950 | C29: =IFERROR(SUMIFS('CALENDARIO INGRESOS'!$I:$I,'CALENDARIO INGRESOS'!$C:$C,Tabla814[[#Headers],[Chile]],'CALENDARIO INGRESOS'!$G:$G,">="&$A29,'CALENDARIO INGRESOS'!$G:$G,"<="&EOMONTH($A29,0)),0) -> 27038 | D29: =IFERROR(SUMIFS('CALENDARIO INGRESOS'!$I:$I,'CALENDARIO INGRESOS'!$C:$C,Tabla814[[#Headers],[Ecuador]],'CALENDARIO INGRESOS'!$G:$G,">="&$A29,'CALENDARIO INGRESOS'!$G:$G,"<="&EOMONTH($A29,0)),0) -> 11800 | E29: =IFERROR(SUMIFS('CALENDARIO INGRESOS'!$I:$I,'CALENDARIO INGRESOS'!$C:$C,Tabla814[[#Headers],[México]],'CALENDARIO INGRESOS'!$G:$G,">="&$A29,'CALENDARIO INGRESOS'!$G:$G,"<="&EOMONTH($A29,0)),0) -> 12804 | F29: =IFERROR(SUMIFS('CALENDARIO INGRESOS'!$I:$I,'CALENDARIO INGRESOS'!$C:$C,Tabla814[[#Headers],[Colombia]],'CALENDARIO INGRESOS'!$G:$G,">="&$A29,'CALENDARIO INGRESOS'!$G:$G,"<="&EOMONTH($A29,0)),0) -> 5200 | G29: =IFERROR(SUMIFS('CALENDARIO INGRESOS'!$I:$I,'CALENDARIO INGRESOS'!$C:$C,Tabla814[[#Headers],[República Dominicana]],'CALENDARIO INGRESOS'!$G:$G,">="&$A29,'CALENDARIO INGRESOS'!$G:$G,"<="&EOMONTH($A29,0)),0) -> 2000 | H29: =IFERROR(SUMIFS('CALENDARIO INGRESOS'!$I:$I,'CALENDARIO INGRESOS'!$C:$C,Tabla814[[#Headers],[Perú]],'CALENDARIO INGRESOS'!$G:$G,">="&$A29,'CALENDARIO INGRESOS'!$G:$G,"<="&EOMONTH($A29,0)),0) -> 8350 | I29: =IFERROR(SUMIFS('CALENDARIO INGRESOS'!$I:$I,'CALENDARIO INGRESOS'!$C:$C,Tabla814[[#Headers],[Paraguay]],'CALENDARIO INGRESOS'!$G:$G,">="&$A29,'CALENDARIO INGRESOS'!$G:$G,"<="&EOMONTH($A29,0)),0) -> 0 | J29: =IFERROR(SUMIFS('CALENDARIO INGRESOS'!$I:$I,'CALENDARIO INGRESOS'!$C:$C,Tabla814[[#Headers],[Honduras]],'CALENDARIO INGRESOS'!$G:$G,">="&$A29,'CALENDARIO INGRESOS'!$G:$G,"<="&EOMONTH($A29,0)),0) -> 2187 | K29: =IFERROR(SUMIFS('CALENDARIO INGRESOS'!$I:$I,'CALENDARIO INGRESOS'!$C:$C,Tabla814[[#Headers],[Bolivia]],'CALENDARIO INGRESOS'!$G:$G,">="&$A29,'CALENDARIO INGRESOS'!$G:$G,"<="&EOMONTH($A29,0)),0) -> 2741 | L29: =IFERROR(SUMIFS('CALENDARIO INGRESOS'!$I:$I,'CALENDARIO INGRESOS'!$C:$C,Tabla814[[#Headers],[Argentina]],'CALENDARIO INGRESOS'!$G:$G,">="&$A29,'CALENDARIO INGRESOS'!$G:$G,"<="&EOMONTH($A29,0)),0) -> 1200 | M29: =IFERROR(SUMIFS('CALENDARIO INGRESOS'!$I:$I,'CALENDARIO INGRESOS'!$C:$C,Tabla814[[#Headers],[Guatemala]],'CALENDARIO INGRESOS'!$G:$G,">="&$A29,'CALENDARIO INGRESOS'!$G:$G,"<="&EOMONTH($A29,0)),0) -> 1600 | N29: =IFERROR(SUMIFS('CALENDARIO INGRESOS'!$I:$I,'CALENDARIO INGRESOS'!$C:$C,Tabla814[[#Headers],[Venezuela]],'CALENDARIO INGRESOS'!$G:$G,">="&$A29,'CALENDARIO INGRESOS'!$G:$G,"<="&EOMONTH($A29,0)),0) -> 0 | O29: =IFERROR(SUMIFS('CALENDARIO INGRESOS'!$I:$I,'CALENDARIO INGRESOS'!$C:$C,Tabla814[[#Headers],[Uruguay]],'CALENDARIO INGRESOS'!$G:$G,">="&$A29,'CALENDARIO INGRESOS'!$G:$G,"<="&EOMONTH($A29,0)),0) -> 0 | P29: =IFERROR(SUMIFS('CALENDARIO INGRESOS'!$I:$I,'CALENDARIO INGRESOS'!$C:$C,Tabla814[[#Headers],[Nicaragua]],'CALENDARIO INGRESOS'!$G:$G,">="&$A29,'CALENDARIO INGRESOS'!$G:$G,"<="&EOMONTH($A29,0)),0) -> 0 | Q29: =+SUM(Tabla814[[#This Row],[El Salvador]:[Nicaragua]]) -> 77870
A30: 46388 | B30: =IFERROR(SUMIFS('CALENDARIO INGRESOS'!$I:$I,'CALENDARIO INGRESOS'!$C:$C,Tabla814[[#Headers],[El Salvador]],'CALENDARIO INGRESOS'!$G:$G,">="&$A30,'CALENDARIO INGRESOS'!$G:$G,"<="&EOMONTH($A30,0)),0) -> 2100 | C30: =IFERROR(SUMIFS('CALENDARIO INGRESOS'!$I:$I,'CALENDARIO INGRESOS'!$C:$C,Tabla814[[#Headers],[Chile]],'CALENDARIO INGRESOS'!$G:$G,">="&$A30,'CALENDARIO INGRESOS'!$G:$G,"<="&EOMONTH($A30,0)),0) -> 23638 | D30: =IFERROR(SUMIFS('CALENDARIO INGRESOS'!$I:$I,'CALENDARIO INGRESOS'!$C:$C,Tabla814[[#Headers],[Ecuador]],'CALENDARIO INGRESOS'!$G:$G,">="&$A30,'CALENDARIO INGRESOS'!$G:$G,"<="&EOMONTH($A30,0)),0) -> 9800 | E30: =IFERROR(SUMIFS('CALENDARIO INGRESOS'!$I:$I,'CALENDARIO INGRESOS'!$C:$C,Tabla814[[#Headers],[México]],'CALENDARIO INGRESOS'!$G:$G,">="&$A30,'CALENDARIO INGRESOS'!$G:$G,"<="&EOMONTH($A30,0)),0) -> 12154 | F30: =IFERROR(SUMIFS('CALENDARIO INGRESOS'!$I:$I,'CALENDARIO INGRESOS'!$C:$C,Tabla814[[#Headers],[Colombia]],'CALENDARIO INGRESOS'!$G:$G,">="&$A30,'CALENDARIO INGRESOS'!$G:$G,"<="&EOMONTH($A30,0)),0) -> 6200 | G30: =IFERROR(SUMIFS('CALENDARIO INGRESOS'!$I:$I,'CALENDARIO INGRESOS'!$C:$C,Tabla814[[#Headers],[República Dominicana]],'CALENDARIO INGRESOS'!$G:$G,">="&$A30,'CALENDARIO INGRESOS'!$G:$G,"<="&EOMONTH($A30,0)),0) -> 2000 | H30: =IFERROR(SUMIFS('CALENDARIO INGRESOS'!$I:$I,'CALENDARIO INGRESOS'!$C:$C,Tabla814[[#Headers],[Perú]],'CALENDARIO INGRESOS'!$G:$G,">="&$A30,'CALENDARIO INGRESOS'!$G:$G,"<="&EOMONTH($A30,0)),0) -> 5850 | I30: =IFERROR(SUMIFS('CALENDARIO INGRESOS'!$I:$I,'CALENDARIO INGRESOS'!$C:$C,Tabla814[[#Headers],[Paraguay]],'CALENDARIO INGRESOS'!$G:$G,">="&$A30,'CALENDARIO INGRESOS'!$G:$G,"<="&EOMONTH($A30,0)),0) -> 0 | J30: =IFERROR(SUMIFS('CALENDARIO INGRESOS'!$I:$I,'CALENDARIO INGRESOS'!$C:$C,Tabla814[[#Headers],[Honduras]],'CALENDARIO INGRESOS'!$G:$G,">="&$A30,'CALENDARIO INGRESOS'!$G:$G,"<="&EOMONTH($A30,0)),0) -> 2000 | K30: =IFERROR(SUMIFS('CALENDARIO INGRESOS'!$I:$I,'CALENDARIO INGRESOS'!$C:$C,Tabla814[[#Headers],[Bolivia]],'CALENDARIO INGRESOS'!$G:$G,">="&$A30,'CALENDARIO INGRESOS'!$G:$G,"<="&EOMONTH($A30,0)),0) -> 0 | L30: =IFERROR(SUMIFS('CALENDARIO INGRESOS'!$I:$I,'CALENDARIO INGRESOS'!$C:$C,Tabla814[[#Headers],[Argentina]],'CALENDARIO INGRESOS'!$G:$G,">="&$A30,'CALENDARIO INGRESOS'!$G:$G,"<="&EOMONTH($A30,0)),0) -> 1200 | M30: =IFERROR(SUMIFS('CALENDARIO INGRESOS'!$I:$I,'CALENDARIO INGRESOS'!$C:$C,Tabla814[[#Headers],[Guatemala]],'CALENDARIO INGRESOS'!$G:$G,">="&$A30,'CALENDARIO INGRESOS'!$G:$G,"<="&EOMONTH($A30,0)),0) -> 1600 | N30: =IFERROR(SUMIFS('CALENDARIO INGRESOS'!$I:$I,'CALENDARIO INGRESOS'!$C:$C,Tabla814[[#Headers],[Venezuela]],'CALENDARIO INGRESOS'!$G:$G,">="&$A30,'CALENDARIO INGRESOS'!$G:$G,"<="&EOMONTH($A30,0)),0) -> 0 | O30: =IFERROR(SUMIFS('CALENDARIO INGRESOS'!$I:$I,'CALENDARIO INGRESOS'!$C:$C,Tabla814[[#Headers],[Uruguay]],'CALENDARIO INGRESOS'!$G:$G,">="&$A30,'CALENDARIO INGRESOS'!$G:$G,"<="&EOMONTH($A30,0)),0) -> 0 | P30: =IFERROR(SUMIFS('CALENDARIO INGRESOS'!$I:$I,'CALENDARIO INGRESOS'!$C:$C,Tabla814[[#Headers],[Nicaragua]],'CALENDARIO INGRESOS'!$G:$G,">="&$A30,'CALENDARIO INGRESOS'!$G:$G,"<="&EOMONTH($A30,0)),0) -> 0 | Q30: =+SUM(Tabla814[[#This Row],[El Salvador]:[Nicaragua]]) -> 66542
... A41: 46722 | B41: =IFERROR(SUMIFS('CALENDARIO INGRESOS'!$I:$I,'CALENDARIO INGRESOS'!$C:$C,Tabla814[[#Headers],[El Salvador]],'CALENDARIO INGRESOS'!$G:$G,">="&$A41,'CALENDARIO INGRESOS'!$G:$G,"<="&EOMONTH($A41,0)),0) -> 800 | C41: =IFERROR(SUMIFS('CALENDARIO INGRESOS'!$I:$I,'CALENDARIO INGRESOS'!$C:$C,Tabla814[[#Headers],[Chile]],'CALENDARIO INGRESOS'!$G:$G,">="&$A41,'CALENDARIO INGRESOS'!$G:$G,"<="&EOMONTH($A41,0)),0) -> 6908 | D41: =IFERROR(SUMIFS('CALENDARIO INGRESOS'!$I:$I,'CALENDARIO INGRESOS'!$C:$C,Tabla814[[#Headers],[Ecuador]],'CALENDARIO INGRESOS'!$G:$G,">="&$A41,'CALENDARIO INGRESOS'!$G:$G,"<="&EOMONTH($A41,0)),0) -> 8950 | E41: =IFERROR(SUMIFS('CALENDARIO INGRESOS'!$I:$I,'CALENDARIO INGRESOS'!$C:$C,Tabla814[[#Headers],[México]],'CALENDARIO INGRESOS'!$G:$G,">="&$A41,'CALENDARIO INGRESOS'!$G:$G,"<="&EOMONTH($A41,0)),0) -> 6750 | F41: =IFERROR(SUMIFS('CALENDARIO INGRESOS'!$I:$I,'CALENDARIO INGRESOS'!$C:$C,Tabla814[[#Headers],[Colombia]],'CALENDARIO INGRESOS'!$G:$G,">="&$A41,'CALENDARIO INGRESOS'!$G:$G,"<="&EOMONTH($A41,0)),0) -> 3450 | G41: =IFERROR(SUMIFS('CALENDARIO INGRESOS'!$I:$I,'CALENDARIO INGRESOS'!$C:$C,Tabla814[[#Headers],[República Dominicana]],'CALENDARIO INGRESOS'!$G:$G,">="&$A41,'CALENDARIO INGRESOS'!$G:$G,"<="&EOMONTH($A41,0)),0) -> 1000 | H41: =IFERROR(SUMIFS('CALENDARIO INGRESOS'!$I:$I,'CALENDARIO INGRESOS'!$C:$C,Tabla814[[#Headers],[Perú]],'CALENDARIO INGRESOS'!$G:$G,">="&$A41,'CALENDARIO INGRESOS'!$G:$G,"<="&EOMONTH($A41,0)),0) -> 3800 | I41: =IFERROR(SUMIFS('CALENDARIO INGRESOS'!$I:$I,'CALENDARIO INGRESOS'!$C:$C,Tabla814[[#Headers],[Paraguay]],'CALENDARIO INGRESOS'!$G:$G,">="&$A41,'CALENDARIO INGRESOS'!$G:$G,"<="&EOMONTH($A41,0)),0) -> 0 | J41: =IFERROR(SUMIFS('CALENDARIO INGRESOS'!$I:$I,'CALENDARIO INGRESOS'!$C:$C,Tabla814[[#Headers],[Honduras]],'CALENDARIO INGRESOS'!$G:$G,">="&$A41,'CALENDARIO INGRESOS'!$G:$G,"<="&EOMONTH($A41,0)),0) -> 0 | K41: =IFERROR(SUMIFS('CALENDARIO INGRESOS'!$I:$I,'CALENDARIO INGRESOS'!$C:$C,Tabla814[[#Headers],[Bolivia]],'CALENDARIO INGRESOS'!$G:$G,">="&$A41,'CALENDARIO INGRESOS'!$G:$G,"<="&EOMONTH($A41,0)),0) -> 0 | L41: =IFERROR(SUMIFS('CALENDARIO INGRESOS'!$I:$I,'CALENDARIO INGRESOS'!$C:$C,Tabla814[[#Headers],[Argentina]],'CALENDARIO INGRESOS'!$G:$G,">="&$A41,'CALENDARIO INGRESOS'!$G:$G,"<="&EOMONTH($A41,0)),0) -> 2000 | M41: =IFERROR(SUMIFS('CALENDARIO INGRESOS'!$I:$I,'CALENDARIO INGRESOS'!$C:$C,Tabla814[[#Headers],[Guatemala]],'CALENDARIO INGRESOS'!$G:$G,">="&$A41,'CALENDARIO INGRESOS'!$G:$G,"<="&EOMONTH($A41,0)),0) -> 0 | N41: =IFERROR(SUMIFS('CALENDARIO INGRESOS'!$I:$I,'CALENDARIO INGRESOS'!$C:$C,Tabla814[[#Headers],[Venezuela]],'CALENDARIO INGRESOS'!$G:$G,">="&$A41,'CALENDARIO INGRESOS'!$G:$G,"<="&EOMONTH($A41,0)),0) -> 1000 | O41: =IFERROR(SUMIFS('CALENDARIO INGRESOS'!$I:$I,'CALENDARIO INGRESOS'!$C:$C,Tabla814[[#Headers],[Uruguay]],'CALENDARIO INGRESOS'!$G:$G,">="&$A41,'CALENDARIO INGRESOS'!$G:$G,"<="&EOMONTH($A41,0)),0) -> 0 | P41: =IFERROR(SUMIFS('CALENDARIO INGRESOS'!$I:$I,'CALENDARIO INGRESOS'!$C:$C,Tabla814[[#Headers],[Nicaragua]],'CALENDARIO INGRESOS'!$G:$G,">="&$A41,'CALENDARIO INGRESOS'!$G:$G,"<="&EOMONTH($A41,0)),0) -> 0 | Q41: =+SUM(Tabla814[[#This Row],[El Salvador]:[Nicaragua]]) -> 34658
A42: TOTAL | B42: =+SUM(B19:B41) -> 71909 | C42: =+SUM(C19:C41) -> 340344.54 | D42: =+SUM(D19:D41) -> 312218 | E42: =+SUM(E19:E41) -> 348930.15 | F42: =+SUM(F19:F41) -> 170150 | G42: =+SUM(G19:G41) -> 41425 | H42: =+SUM(H19:H41) -> 163103 | I42: =+SUM(I19:I41) -> 0 | ... P42: =+SUM(P19:P41) -> 0 | Q42: =+SUM(Tabla814[[#This Row],[El Salvador]:[Nicaragua]]) -> 1607499.7

Sheet UNIT ECONOMICS
A1: General | D1: Ingreso | F1: COR/Dr (Costo Directo) | J1: Adquisición | K1: OPEX/Dr (Prorrateado) | N1: Resumen/Dr
